Workbook

Sheet 5TR1_1 Gücü ve Akım 
A1: Direk No | B1: Hat No | C1: Mesafe | D1: Kat Sayısı | E1: Güç Yoğunluğu | F1: Hat Gücü | G1: Direk Gücü | H1: Direk Akımı | I1: Hat Akımı | J1: Moment | K1: Toplam Moment | L1: Kesit | M1: Önerilen Hat tertibi | N1: Tercih edilen Hat tertibi | O1: Hat Seçimi | P1: Isıya göre kontrol
A2: TR1_1 | G2: =0.5*F3 -> 2025 | H2: =G2/(SQRT(3)*380) -> 3.0766692
A3: 1 | B3: 1 | C3: 30 | D3: 3 | E3: 45 | F3: =C3*D3*E3 -> 4050 | G3: =0.5*(F3+F4) -> 4050 | H3: =G3/(SQRT(3)*380) -> 6.1533384 | I3: =H3+I4 -> 152.19257 | J3: =I3*C3 -> 4565.7771 | K3: =J3+K4 -> 24204.157 | L3: =K3/(8*35) -> 86.443416 | M3: =IF(L3>Veriler!$D$1,IF(L3>Veriler!$D$2,IF(L3>Veriler!$D$3,IF(L3>Veriler!$D$4,IF(L3>Veriler!$D$5,IF(L3>Veriler!$D$6,IF(L3>Veriler!$D$7,IF(L3>Veriler!$D$8,"ders sorumlusuna başvur",Veriler!$A$8),Veriler!$A$7),Veriler!$A$6),Veriler!$A$5),Veriler!$A$4),Veriler!$A$3),Veriler!$A$2),Veriler!$A$1) -> 8 | N3: 8 | O3: =VLOOKUP(N3,Veriler!A$1:C$8,2,FALSE) -> 3xOxlip+Rose/Aster | P3: =IF(I4<VLOOKUP(N4,Veriler!A$1:E$8,5,FALSE)," UYGUNDUR","KESİT AKIMI TAŞIYAMIYOR") -> UYGUNDUR
A4: 2 | B4: 2 | C4: 30 | D4: 3 | E4: 45 | F4: =C4*D4*E4 -> 4050 | G4: =0.5*(F4+F5) -> 4050 | H4: =G4/(SQRT(3)*380) -> 6.1533384 | I4: =H4+I5 -> 146.03923 | J4: =I4*C4 -> 4381.1769 | K4: =J4+K5 -> 19638.379 | L4: =K4/(8*35) -> 70.13707 | M4: =IF(L4>Veriler!$D$1,IF(L4>Veriler!$D$2,IF(L4>Veriler!$D$3,IF(L4>Veriler!$D$4,IF(L4>Veriler!$D$5,IF(L4>Veriler!$D$6,IF(L4>Veriler!$D$7,IF(L4>Veriler!$D$8,"ders sorumlusuna başvur",Veriler!$A$8),Veriler!$A$7),Veriler!$A$6),Veriler!$A$5),Veriler!$A$4),Veriler!$A$3),Veriler!$A$2),Veriler!$A$1) -> 7 | N4: 8 | O4: =VLOOKUP(N4,Veriler!A$1:C$8,2,FALSE) -> 3xOxlip+Rose/Aster | P4: =IF(I4<VLOOKUP(N4,Veriler!A$1:E$8,5,FALSE)," UYGUNDUR","KESİT AKIMI TAŞIYAMIYOR") -> UYGUNDUR
A5: 3 | B5: 3 | C5: 30 | D5: 3 | E5: 45 | F5: =C5*D5*E5 -> 4050 | G5: =0.5*(F5+F6) -> 3847.5 | H5: =G5/(SQRT(3)*380) -> 5.8456715 | I5: =H5+I6 -> 139.88589 | J5: =I5*C5 -> 4196.5768 | K5: =J5+K6 -> 15257.203 | L5: =K5/(8*35) -> 54.490009 | M5: =IF(L5>Veriler!$D$1,IF(L5>Veriler!$D$2,IF(L5>Veriler!$D$3,IF(L5>Veriler!$D$4,IF(L5>Veriler!$D$5,IF(L5>Veriler!$D$6,IF(L5>Veriler!$D$7,IF(L5>Veriler!$D$8,"ders sorumlusuna başvur",Veriler!$A$8),Veriler!$A$7),Veriler!$A$6),Veriler!$A$5),Veriler!$A$4),Veriler!$A$3),Veriler!$A$2),Veriler!$A$1) -> 6 | N5: 8 | O5: =VLOOKUP(N5,Veriler!A$1:C$8,2,FALSE) -> 3xOxlip+Rose/Aster | P5: =IF(I5<VLOOKUP(N5,Veriler!A$1:E$8,5,FALSE)," UYGUNDUR","KESİT AKIMI TAŞIYAMIYOR") -> UYGUNDUR
A6: 4 | B6: 4 | C6: 27 | D6: 3 | E6: 45 | F6: =C6*D6*E6 -> 3645 | G6: =0.5*(F6+F7+F12) -> 6412.5 | H6: =G6/(SQRT(3)*380) -> 9.7427858 | I6: =H6+H7+H8+H9+H10+I11 -> 134.04022 | J6: =I6*C6 -> 3619.086 | K6: =J6+K11 -> 11060.626 | L6: =K6/(8*35) -> 39.502235 | M6: =IF(L6>Veriler!$D$1,IF(L6>Veriler!$D$2,IF(L6>Veriler!$D$3,IF(L6>Veriler!$D$4,IF(L6>Veriler!$D$5,IF(L6>Veriler!$D$6,IF(L6>Veriler!$D$7,IF(L6>Veriler!$D$8,"ders sorumlusuna başvur",Veriler!$A$8),Veriler!$A$7),Veriler!$A$6),Veriler!$A$5),Veriler!$A$4),Veriler!$A$3),Veriler!$A$2),Veriler!$A$1) -> 4 | N6: 8 | O6: =VLOOKUP(N6,Veriler!A$1:C$8,2,FALSE) -> 3xOxlip+Rose/Aster | P6: =IF(I6<VLOOKUP(N6,Veriler!A$1:E$8,5,FALSE)," UYGUNDUR","KESİT AKIMI TAŞIYAMIYOR") -> UYGUNDUR
A7: 5 | B7: 5 | C7: 34 | D7: 3 | E7: 45 | F7: =C7*D7*E7 -> 4590 | G7: =0.5*(F7+F8) -> 4590 | H7: =G7/(SQRT(3)*380) -> 6.9737835 | M7: =IF(L7>Veriler!$D$1,IF(L7>Veriler!$D$2,IF(L7>Veriler!$D$3,IF(L7>Veriler!$D$4,IF(L7>Veriler!$D$5,IF(L7>Veriler!$D$6,IF(L7>Veriler!$D$7,IF(L7>Veriler!$D$8,"ders sorumlusuna başvur",Veriler!$A$8),Veriler!$A$7),Veriler!$A$6),Veriler!$A$5),Veriler!$A$4),Veriler!$A$3),Veriler!$A$2),Veriler!$A$1) -> 1 | N7: 1 | O7: =VLOOKUP(N7,Veriler!A$1:C$8,2,FALSE) -> 5 x Rose | P7: =IF(I7<VLOOKUP(N7,Veriler!A$1:E$8,5,FALSE)," UYGUNDUR","KESİT AKIMI TAŞIYAMIYOR") -> UYGUNDUR
A8: 6 | B8: 6 | C8: 34 | D8: 3 | E8: 45 | F8: =C8*D8*E8 -> 4590 | G8: =0.5*(F8+F9) -> 4590 | H8: =G8/(SQRT(3)*380) -> 6.9737835 | M8: =IF(L8>Veriler!$D$1,IF(L8>Veriler!$D$2,IF(L8>Veriler!$D$3,IF(L8>Veriler!$D$4,IF(L8>Veriler!$D$5,IF(L8>Veriler!$D$6,IF(L8>Veriler!$D$7,IF(L8>Veriler!$D$8,"ders sorumlusuna başvur",Veriler!$A$8),Veriler!$A$7),Veriler!$A$6),Veriler!$A$5),Veriler!$A$4),Veriler!$A$3),Veriler!$A$2),Veriler!$A$1) -> 1 | N8: 1 | O8: =VLOOKUP(N8,Veriler!A$1:C$8,2,FALSE) -> 5 x Rose | P8: =IF(I8<VLOOKUP(N8,Veriler!A$1:E$8,5,FALSE)," UYGUNDUR","KESİT AKIMI TAŞIYAMIYOR") -> UYGUNDUR
A9: 7 | B9: 7 | C9: 34 | D9: 3 | E9: 45 | F9: =C9*D9*E9 -> 4590 | G9: =0.5*(F9+F10) -> 4590 | H9: =G9/(SQRT(3)*380) -> 6.9737835 | M9: =IF(L9>Veriler!$D$1,IF(L9>Veriler!$D$2,IF(L9>Veriler!$D$3,IF(L9>Veriler!$D$4,IF(L9>Veriler!$D$5,IF(L9>Veriler!$D$6,IF(L9>Veriler!$D$7,IF(L9>Veriler!$D$8,"ders sorumlusuna başvur",Veriler!$A$8),Veriler!$A$7),Veriler!$A$6),Veriler!$A$5),Veriler!$A$4),Veriler!$A$3),Veriler!$A$2),Veriler!$A$1) -> 1 | N9: 1 | O9: =VLOOKUP(N9,Veriler!A$1:C$8,2,FALSE) -> 5 x Rose | P9: =IF(I9<VLOOKUP(N9,Veriler!A$1:E$8,5,FALSE)," UYGUNDUR","KESİT AKIMI TAŞIYAMIYOR") -> UYGUNDUR
A10: 8 | B10: 8 | C10: 34 | D10: 3 | E10: 45 | F10: =C10*D10*E10 -> 4590 | G10: =0.5*(F10+F11) -> 4590 | H10: =G10/(SQRT(3)*380) -> 6.9737835 | M10: =IF(L10>Veriler!$D$1,IF(L10>Veriler!$D$2,IF(L10>Veriler!$D$3,IF(L10>Veriler!$D$4,IF(L10>Veriler!$D$5,IF(L10>Veriler!$D$6,IF(L10>Veriler!$D$7,IF(L10>Veriler!$D$8,"ders sorumlusuna başvur",Veriler!$A$8),Veriler!$A$7),Veriler!$A$6),Veriler!$A$5),Veriler!$A$4),Veriler!$A$3),Veriler!$A$2),Veriler!$A$1) -> 1 | N10: 1 | O10: =VLOOKUP(N10,Veriler!A$1:C$8,2,FALSE) -> 5 x Rose | P10: =IF(I10<VLOOKUP(N10,Veriler!A$1:E$8,5,FALSE)," UYGUNDUR","KESİT AKIMI TAŞIYAMIYOR") -> UYGUNDUR
A11: 9 | B11: 9 | C11: 34 | D11: 3 | E11: 45 | F11: =C11*D11*E11 -> 4590 | G11: =0.5*(F11+F12) -> 4590 | H11: =G11/(SQRT(3)*380) -> 6.9737835 | I11: =H11+H12+H13+H14+H15+H16+H17+I18 -> 96.402302 | J11: =I11*C11 -> 3277.6783 | K11: =J11+K18 -> 7441.5398 | L11: =K11/(8*35) -> 26.576928 | M11: =IF(L11>Veriler!$D$1,IF(L11>Veriler!$D$2,IF(L11>Veriler!$D$3,IF(L11>Veriler!$D$4,IF(L11>Veriler!$D$5,IF(L11>Veriler!$D$6,IF(L11>Veriler!$D$7,IF(L11>Veriler!$D$8,"ders sorumlusuna başvur",Veriler!$A$8),Veriler!$A$7),Veriler!$A$6),Veriler!$A$5),Veriler!$A$4),Veriler!$A$3),Veriler!$A$2),Veriler!$A$1) -> 2 | N11: 2 | O11: =VLOOKUP(N11,Veriler!A$1:C$8,2,FALSE) -> 3 x Lily + Rose/Lily | P11: =IF(I11<VLOOKUP(N11,Veriler!A$1:E$8,5,FALSE)," UYGUNDUR","KESİT AKIMI TAŞIYAMIYOR") -> UYGUNDUR
A12: 10 | B12: 10 | C12: 34 | D12: 3 | E12: 45 | F12: =C12*D12*E12 -> 4590 | G12: =0.5*(F12+F13) -> 4590 | H12: =G12/(SQRT(3)*380) -> 6.9737835 | M12: =IF(L12>Veriler!$D$1,IF(L12>Veriler!$D$2,IF(L12>Veriler!$D$3,IF(L12>Veriler!$D$4,IF(L12>Veriler!$D$5,IF(L12>Veriler!$D$6,IF(L12>Veriler!$D$7,IF(L12>Veriler!$D$8,"ders sorumlusuna başvur",Veriler!$A$8),Veriler!$A$7),Veriler!$A$6),Veriler!$A$5),Veriler!$A$4),Veriler!$A$3),Veriler!$A$2),Veriler!$A$1) -> 1 | N12: 1 | O12: =VLOOKUP(N12,Veriler!A$1:C$8,2,FALSE) -> 5 x Rose | P12: =IF(I12<VLOOKUP(N12,Veriler!A$1:E$8,5,FALSE)," UYGUNDUR","KESİT AKIMI TAŞIYAMIYOR") -> UYGUNDUR
A13: 11 | B13: 11 | C13: 34 | D13: 3 | E13: 45 | F13: =C13*D13*E13 -> 4590 | G13: =0.5*(F13+F14) -> 4590 | H13: =G13/(SQRT(3)*380) -> 6.9737835 | M13: =IF(L13>Veriler!$D$1,IF(L13>Veriler!$D$2,IF(L13>Veriler!$D$3,IF(L13>Veriler!$D$4,IF(L13>Veriler!$D$5,IF(L13>Veriler!$D$6,IF(L13>Veriler!$D$7,IF(L13>Veriler!$D$8,"ders sorumlusuna başvur",Veriler!$A$8),Veriler!$A$7),Veriler!$A$6),Veriler!$A$5),Veriler!$A$4),Veriler!$A$3),Veriler!$A$2),Veriler!$A$1) -> 1 | N13: 1 | O13: =VLOOKUP(N13,Veriler!A$1:C$8,2,FALSE) -> 5 x Rose | P13: =IF(I13<VLOOKUP(N13,Veriler!A$1:E$8,5,FALSE)," UYGUNDUR","KESİT AKIMI TAŞIYAMIYOR") -> UYGUNDUR
A14: 12 | B14: 12 | C14: 34 | D14: 3 | E14: 45 | F14: =C14*D14*E14 -> 4590 | G14: =0.5*(F14+F15+F16) -> 7290 | H14: =G14/(SQRT(3)*380) -> 11.076009 | M14: =IF(L14>Veriler!$D$1,IF(L14>Veriler!$D$2,IF(L14>Veriler!$D$3,IF(L14>Veriler!$D$4,IF(L14>Veriler!$D$5,IF(L14>Veriler!$D$6,IF(L14>Veriler!$D$7,IF(L14>Veriler!$D$8,"ders sorumlusuna başvur",Veriler!$A$8),Veriler!$A$7),Veriler!$A$6),Veriler!$A$5),Veriler!$A$4),Veriler!$A$3),Veriler!$A$2),Veriler!$A$1) -> 1 | N14: 1 | O14: =VLOOKUP(N14,Veriler!A$1:C$8,2,FALSE) -> 5 x Rose | P14: =IF(I14<VLOOKUP(N14,Veriler!A$1:E$8,5,FALSE)," UYGUNDUR","KESİT AKIMI TAŞIYAMIYOR") -> UYGUNDUR
A15: 13 | B15: 13 | C15: 34 | D15: 3 | E15: 45 | F15: =C15*D15*E15 -> 4590 | G15: =0.5*(F15) -> 2295 | H15: =G15/(SQRT(3)*380) -> 3.4868918 | M15: =IF(L15>Veriler!$D$1,IF(L15>Veriler!$D$2,IF(L15>Veriler!$D$3,IF(L15>Veriler!$D$4,IF(L15>Veriler!$D$5,IF(L15>Veriler!$D$6,IF(L15>Veriler!$D$7,IF(L15>Veriler!$D$8,"ders sorumlusuna başvur",Veriler!$A$8),Veriler!$A$7),Veriler!$A$6),Veriler!$A$5),Veriler!$A$4),Veriler!$A$3),Veriler!$A$2),Veriler!$A$1) -> 1 | N15: 1 | O15: =VLOOKUP(N15,Veriler!A$1:C$8,2,FALSE) -> 5 x Rose | P15: =IF(I15<VLOOKUP(N15,Veriler!A$1:E$8,5,FALSE)," UYGUNDUR","KESİT AKIMI TAŞIYAMIYOR") -> UYGUNDUR
A16: 14 | B16: 14 | C16: 40 | D16: 3 | E16: 45 | F16: =C16*D16*E16 -> 5400 | G16: =0.5*(F16+F17) -> 5400 | H16: =G16/(SQRT(3)*380) -> 8.2044512 | M16: =IF(L16>Veriler!$D$1,IF(L16>Veriler!$D$2,IF(L16>Veriler!$D$3,IF(L16>Veriler!$D$4,IF(L16>Veriler!$D$5,IF(L16>Veriler!$D$6,IF(L16>Veriler!$D$7,IF(L16>Veriler!$D$8,"ders sorumlusuna başvur",Veriler!$A$8),Veriler!$A$7),Veriler!$A$6),Veriler!$A$5),Veriler!$A$4),Veriler!$A$3),Veriler!$A$2),Veriler!$A$1) -> 1 | N16: 1 | O16: =VLOOKUP(N16,Veriler!A$1:C$8,2,FALSE) -> 5 x Rose | P16: =IF(I16<VLOOKUP(N16,Veriler!A$1:E$8,5,FALSE)," UYGUNDUR","KESİT AKIMI TAŞIYAMIYOR") -> UYGUNDUR
A17: 15 | B17: 15 | C17: 40 | D17: 3 | E17: 45 | F17: =C17*D17*E17 -> 5400 | G17: =0.5*(F17) -> 2700 | H17: =G17/(SQRT(3)*380) -> 4.1022256 | M17: =IF(L17>Veriler!$D$1,IF(L17>Veriler!$D$2,IF(L17>Veriler!$D$3,IF(L17>Veriler!$D$4,IF(L17>Veriler!$D$5,IF(L17>Veriler!$D$6,IF(L17>Veriler!$D$7,IF(L17>Veriler!$D$8,"ders sorumlusuna başvur",Veriler!$A$8),Veriler!$A$7),Veriler!$A$6),Veriler!$A$5),Veriler!$A$4),Veriler!$A$3),Veriler!$A$2),Veriler!$A$1) -> 1 | N17: 1 | O17: =VLOOKUP(N17,Veriler!A$1:C$8,2,FALSE) -> 5 x Rose | P17: =IF(I17<VLOOKUP(N17,Veriler!A$1:E$8,5,FALSE)," UYGUNDUR","KESİT AKIMI TAŞIYAMIYOR") -> UYGUNDUR
A18: 16 | B18: 16 | C18: 28 | D18: 3 | E18: 45 | F18: =C18*D18*E18 -> 3780 | G18: =0.5*(F18+F19) -> 3780 | H18: =G18/(SQRT(3)*380) -> 5.7431158 | I18: =H18+I19 -> 48.611373 | J18: =I18*C18 -> 1361.1185 | K18: =J18+K19 -> 4163.8615 | L18: =K18/(8*35) -> 14.870934 | M18: =IF(L18>Veriler!$D$1,IF(L18>Veriler!$D$2,IF(L18>Veriler!$D$3,IF(L18>Veriler!$D$4,IF(L18>Veriler!$D$5,IF(L18>Veriler!$D$6,IF(L18>Veriler!$D$7,IF(L18>Veriler!$D$8,"ders sorumlusuna başvur",Veriler!$A$8),Veriler!$A$7),Veriler!$A$6),Veriler!$A$5),Veriler!$A$4),Veriler!$A$3),Veriler!$A$2),Veriler!$A$1) -> 1 | N18: 1 | O18: =VLOOKUP(N18,Veriler!A$1:C$8,2,FALSE) -> 5 x Rose | P18: =IF(I18<VLOOKUP(N18,Veriler!A$1:E$8,5,FALSE)," UYGUNDUR","KESİT AKIMI TAŞIYAMIYOR") -> UYGUNDUR
A19: 17 | B19: 17 | C19: 28 | D19: 3 | E19: 45 | F19: =C19*D19*E19 -> 3780 | G19: =0.5*(F19+F20+F22) -> 6952.5 | H19: =G19/(SQRT(3)*380) -> 10.563231 | I19: =H19+H20+H21+I22 -> 42.868257 | J19: =I19*C19 -> 1200.3112 | K19: =J19+K22 -> 2802.7431 | L19: =K19/(8*35) -> 10.009797 | M19: =IF(L19>Veriler!$D$1,IF(L19>Veriler!$D$2,IF(L19>Veriler!$D$3,IF(L19>Veriler!$D$4,IF(L19>Veriler!$D$5,IF(L19>Veriler!$D$6,IF(L19>Veriler!$D$7,IF(L19>Veriler!$D$8,"ders sorumlusuna başvur",Veriler!$A$8),Veriler!$A$7),Veriler!$A$6),Veriler!$A$5),Veriler!$A$4),Veriler!$A$3),Veriler!$A$2),Veriler!$A$1) -> 1 | N19: 1 | O19: =VLOOKUP(N16,Veriler!A$1:C$8,2,FALSE) -> 5 x Rose | P19: =IF(I19<VLOOKUP(N19,Veriler!A$1:E$8,5,FALSE)," UYGUNDUR","KESİT AKIMI TAŞIYAMIYOR") -> UYGUNDUR
A20: 18 | B20: 18 | C20: 35 | D20: 3 | E20: 45 | F20: =C20*D20*E20 -> 4725 | G20: =0.5*(F20+F21) -> 4725 | H20: =G20/(SQRT(3)*380) -> 7.1788948 | M20: =IF(L20>Veriler!$D$1,IF(L20>Veriler!$D$2,IF(L20>Veriler!$D$3,IF(L20>Veriler!$D$4,IF(L20>Veriler!$D$5,IF(L20>Veriler!$D$6,IF(L20>Veriler!$D$7,IF(L20>Veriler!$D$8,"ders sorumlusuna başvur",Veriler!$A$8),Veriler!$A$7),Veriler!$A$6),Veriler!$A$5),Veriler!$A$4),Veriler!$A$3),Veriler!$A$2),Veriler!$A$1) -> 1 | N20: 1 | O20: =VLOOKUP(N17,Veriler!A$1:C$8,2,FALSE) -> 5 x Rose | P20: =IF(I20<VLOOKUP(N20,Veriler!A$1:E$8,5,FALSE)," UYGUNDUR","KESİT AKIMI TAŞIYAMIYOR") -> UYGUNDUR
A21: 19 | B21: 19 | C21: 35 | D21: 3 | E21: 45 | F21: =C21*D21*E21 -> 4725 | G21: =0.5*(F21) -> 2362.5 | H21: =G21/(SQRT(3)*380) -> 3.5894474 | M21: =IF(L21>Veriler!$D$1,IF(L21>Veriler!$D$2,IF(L21>Veriler!$D$3,IF(L21>Veriler!$D$4,IF(L21>Veriler!$D$5,IF(L21>Veriler!$D$6,IF(L21>Veriler!$D$7,IF(L21>Veriler!$D$8,"ders sorumlusuna başvur",Veriler!$A$8),Veriler!$A$7),Veriler!$A$6),Veriler!$A$5),Veriler!$A$4),Veriler!$A$3),Veriler!$A$2),Veriler!$A$1) -> 1 | N21: 1 | O21: =VLOOKUP(N18,Veriler!A$1:C$8,2,FALSE) -> 5 x Rose | P21: =IF(I21<VLOOKUP(N21,Veriler!A$1:E$8,5,FALSE)," UYGUNDUR","KESİT AKIMI TAŞIYAMIYOR") -> UYGUNDUR
A22: 20 | B22: 20 | C22: 40 | D22: 3 | E22: 45 | F22: =C22*D22*E22 -> 5400 | G22: =0.5*(F22+F23) -> 5737.5 | H22: =G22/(SQRT(3)*380) -> 8.7172294 | I22: =H22+I23 -> 21.536684 | J22: =I22*C22 -> 861.46738 | K22: =J22+K23 -> 1602.4319 | L22: =K22/(8*35) -> 5.722971 | M22: =IF(L22>Veriler!$D$1,IF(L22>Veriler!$D$2,IF(L22>Veriler!$D$3,IF(L22>Veriler!$D$4,IF(L22>Veriler!$D$5,IF(L22>Veriler!$D$6,IF(L22>Veriler!$D$7,IF(L22>Veriler!$D$8,"ders sorumlusuna başvur",Veriler!$A$8),Veriler!$A$7),Veriler!$A$6),Veriler!$A$5),Veriler!$A$4),Veriler!$A$3),Veriler!$A$2),Veriler!$A$1) -> 1 | N22: 1 | O22: =VLOOKUP(N19,Veriler!A$1:C$8,2,FALSE) -> 5 x Rose | P22: =IF(I22<VLOOKUP(N22,Veriler!A$1:E$8,5,FALSE)," UYGUNDUR","KESİT AKIMI TAŞIYAMIYOR") -> UYGUNDUR
A23: 21 | B23: 21 | C23: 45 | D23: 3 | E23: 45 | F23: =C23*D23*E23 -> 6075 | G23: =0.5*(F23+F24) -> 5737.5 | H23: =G23/(SQRT(3)*380) -> 8.7172294 | I23: =H23+I24 -> 12.819455 | J23: =I23*C23 -> 576.87547 | K23: =J23+K24 -> 740.9645 | L23: =K23/(8*35) -> 2.6463018 | M23: =IF(L23>Veriler!$D$1,IF(L23>Veriler!$D$2,IF(L23>Veriler!$D$3,IF(L23>Veriler!$D$4,IF(L23>Veriler!$D$5,IF(L23>Veriler!$D$6,IF(L23>Veriler!$D$7,IF(L23>Veriler!$D$8,"ders sorumlusuna başvur",Veriler!$A$8),Veriler!$A$7),Veriler!$A$6),Veriler!$A$5),Veriler!$A$4),Veriler!$A$3),Veriler!$A$2),Veriler!$A$1) -> 1 | N23: 1 | O23: =VLOOKUP(N20,Veriler!A$1:C$8,2,FALSE) -> 5 x Rose | P23: =IF(I23<VLOOKUP(N23,Veriler!A$1:E$8,5,FALSE)," UYGUNDUR","KESİT AKIMI TAŞIYAMIYOR") -> UYGUNDUR
A24: 22 | B24: 22 | C24: 40 | D24: 3 | E24: 45 | F24: =C24*D24*E24 -> 5400 | G24: =0.5*(F24) -> 2700 | H24: =G24/(SQRT(3)*380) -> 4.1022256 | I24: 4.1022256 | J24: =I24*C24 -> 164.08902 | K24: 164.08902 | L24: =K24/(8*35) -> 0.58603223 | M24: =IF(L24>Veriler!$D$1,IF(L24>Veriler!$D$2,IF(L24>Veriler!$D$3,IF(L24>Veriler!$D$4,IF(L24>Veriler!$D$5,IF(L24>Veriler!$D$6,IF(L24>Veriler!$D$7,IF(L24>Veriler!$D$8,"ders sorumlusuna başvur",Veriler!$A$8),Veriler!$A$7),Veriler!$A$6),Veriler!$A$5),Veriler!$A$4),Veriler!$A$3),Veriler!$A$2),Veriler!$A$1) -> 1 | N24: 1 | O24: =VLOOKUP(N21,Veriler!A$1:C$8,2,FALSE) -> 5 x Rose | P24: =IF(I24<VLOOKUP(N24,Veriler!A$1:E$8,5,FALSE)," UYGUNDUR","KESİT AKIMI TAŞIYAMIYOR") -> UYGUNDUR

Sheet 5TR1-1Abone
A1: AKTİF GÜÇ
A2: Branşman Noktasına İrca Edilen Yük | G2: 58.5 | I2: 201 | K2: 250.5 | M2: 160.5 | O2: 62.5
A3: Hat Yükleri (m) | F3: =H3+G2 -> 733 | H3: =J3+I2 -> 674.5 | J3: =L3+K2 -> 473.5 | L3: =N3+M2 -> 223 | N3: 62.5
A4: Güç Yoğunluğu (J) | F4: 45 | H4: 45 | J4: 45 | L4: 45 | N4: 45
A5: Ktri | F5: 4.96 | H5: 19.8 | J5: 7.42 | L5: 9.36 | N5: 9.3
A6: %e | F6: =F5*F4*F3*G2*10^-7 -> 0.95709276 | H6: =H5*H4*H3*10^-7*117 -> 7.0314602 | J6: =J5*J4*J3*10^-7*13 -> 0.20553214 | L6: =L5*L4*L3*10^-7*56 -> 0.52599456 | N6: =N5*N4*N3*10^-7*125 -> 0.32695313

Sheet 5TR1-1Aydınlatma
A1: AKTİF GÜÇ
A2: Branşman Noktasına İrca Edilen Yük | B2: 125 | C2: 125 | D2: 125 | E2: 625 | F2: 875 | G2: 125 | H2: 375 | I2: 125 | J2: 125 | K2: 125
A3: Hat Yükleri (m) | B3: 750 | C3: 2625 | D3: 2500 | E3: 2375 | F3: 1750 | G3: 875 | H3: 750 | I3: 375 | J3: 250 | K3: 125
A4: Kmono | B4: 36.65 | C4: 55.8 | D4: 55.8 | E4: 55.8 | F4: 55.8 | G4: 55.8 | H4: 55.8 | I4: 36.65 | J4: 36.65 | K4: 36.65
A5: %e | B5: =B4*B3*B2*10^-7 -> 0.34359375 | C5: =C4*C3*C2*10^-7 -> 1.8309375 | D5: =D4*D2*10^-7 -> 0.0006975 | E5: =E4*E3*10^-7 -> 0.0132525 | F5: =F4*F2*10^-7 -> 0.0048825 | G5: =G4*G3*G2*10^-7 -> 0.6103125 | H5: =H4*H3*H2*10^-7 -> 1.569375 | I5: =I4*I3*I2*10^-7 -> 0.17179687 | J5: =J4*J3*J2*10^-7 -> 0.11453125 | K5: =K4*K3*K2*10^-7 -> 0.057265625
B6: =B5+C5+D5+E5+F5+G5+H5+I5+J5+K5 -> 4.716645

Sheet TR1_1  Moment
A1: Moment | B1: Toplam Moment | C1: Kesit | D1: Önerilen Hat tertibi | E1: Tercih edilen Hat tertibi | F1: Hat Seçimi | G1: Isıya göre kontrol
A3: 4565.7771 | B3: 24204.157 | C3: 86.443416 | D3: 8 | E3: 8 | F3: 3xOxlip+Rose/Aster | G3: UYGUNDUR
A4: 4381.1769 | B4: 19638.379 | C4: 70.13707 | D4: 7 | E4: 8 | F4: 3xOxlip+Rose/Aster | G4: UYGUNDUR
A5: 4196.5768 | B5: 15257.203 | C5: 54.490009 | D5: 6 | E5: 8 | F5: 3xOxlip+Rose/Aster | G5: UYGUNDUR
A6: 3619.086 | B6: 11060.626 | C6: 39.502235 | D6: 4 | E6: 8 | F6: 3xOxlip+Rose/Aster | G6: UYGUNDUR
D7: 1 | E7: 1 | F7: 5 x Rose | G7: UYGUNDUR
D8: 1 | E8: 1 | F8: 5 x Rose | G8: UYGUNDUR
D9: 1 | E9: 1 | F9: 5 x Rose | G9: UYGUNDUR
D10: 1 | E10: 1 | F10: 5 x Rose | G10: UYGUNDUR
A11: 3277.6783 | B11: 7441.5398 | C11: 26.576928 | D11: 2 | E11: 2 | F11: 3 x Lily + Rose/Lily | G11: UYGUNDUR
D12: 1 | E12: 1 | F12: 5 x Rose | G12: UYGUNDUR
D13: 1 | E13: 1 | F13: 5 x Rose | G13: UYGUNDUR
D14: 1 | E14: 1 | F14: 5 x Rose | G14: UYGUNDUR
D15: 1 | E15: 1 | F15: 5 x Rose | G15: UYGUNDUR
D16: 1 | E16: 1 | F16: 5 x Rose | G16: UYGUNDUR
D17: 1 | E17: 1 | F17: 5 x Rose | G17: UYGUNDUR
A18: 1361.1185 | B18: 4163.8615 | C18: 14.870934 | D18: 1 | E18: 1 | F18: 5 x Rose | G18: UYGUNDUR
A19: 1200.3112 | B19: 2802.7431 | C19: 10.009797 | D19: 1 | E19: 1 | F19: 5 x Rose | G19: UYGUNDUR
D20: 1 | E20: 1 | F20: 5 x Rose | G20: UYGUNDUR
D21: 1 | E21: 1 | F21: 5 x Rose | G21: UYGUNDUR
A22: 861.46738 | B22: 1602.4319 | C22: 5.722971 | D22: 1 | E22: 1 | F22: 5 x Rose | G22: UYGUNDUR
A23: 576.87547 | B23: 740.9645 | C23: 2.6463018 | D23: 1 | E23: 1 | F23: 5 x Rose | G23: UYGUNDUR
A24: 164.08902 | B24: 164.08902 | C24: 0.58603223 | D24: 1 | E24: 1 | F24: 5 x Rose | G24: UYGUNDUR

Sheet 5TR1_2 Gücü ve Akım
A1: Direk No | B1: Hat No | C1: Mesafe | D1: Kat Sayısı | E1: Güç Yoğunluğu | F1: Hat Gücü | G1: Direk Gücü | H1: Direk Akımı | I1: Hat Akımı | J1: Moment | K1: Toplam Moment | L1: Kesit | M1: Önerilen Hat tertibi | N1: Tercih edilen Hat tertibi | O1: Hat Seçimi | P1: Isıya göre kontrol
A2: TR1_2 | G2: =0.5*F3 -> 2362.5 | H2: =G2/(SQRT(3)*380) -> 3.5894474
A3: 23 | B3: 23 | C3: 35 | D3: 3 | E3: 45 | F3: =C3*D3*E3 -> 4725 | G3: =0.5*(F3+F4) -> 4725 | H3: =G3/(SQRT(3)*380) -> 7.1788948 | I3: =H3+I4 -> 95.240004 | J3: =I3*C3 -> 3333.4001 | K3: =J3+K4 -> 28712.434 | L3: =K3/(8*35) -> 102.54441 | M3: =IF(L3>[2]Veriler!$D$1,IF(L3>[2]Veriler!$D$2,IF(L3>[2]Veriler!$D$3,IF(L3>[2]Veriler!$D$4,IF(L3>[2]Veriler!$D$5,IF(L3>[2]Veriler!$D$6,IF(L3>[2]Veriler!$D$7,IF(L3>[2]Veriler!$D$8,"ders sorumlusuna başvur",[2]Veriler!$A$8),[2]Veriler!$A$7),[2]Veriler!$A$6),[2]Veriler!$A$5),[2]Veriler!$A$4),[2]Veriler!$A$3),[2]Veriler!$A$2),[2]Veriler!$A$1) -> 8 | N3: 8 | O3: =VLOOKUP(N3,[2]Veriler!A$1:C$8,2,FALSE) -> 3xOxlip+Rose/Aster | P3: =IF(I4<VLOOKUP(N4,[2]Veriler!A$1:E$8,5,FALSE)," UYGUNDUR","KESİT AKIMI TAŞIYAMIYOR") -> UYGUNDUR
A4: 24 | B4: 24 | C4: 35 | D4: 3 | E4: 45 | F4: =C4*D4*E4 -> 4725 | G4: =0.5*(F4+F5) -> 4725 | H4: =G4/(SQRT(3)*380) -> 7.1788948 | I4: =H4+I5 -> 88.061109 | J4: =I4*C4 -> 3082.1388 | K4: =J4+K5 -> 25379.034 | L4: =K4/(8*35) -> 90.639407 | M4: =IF(L4>[2]Veriler!$D$1,IF(L4>[2]Veriler!$D$2,IF(L4>[2]Veriler!$D$3,IF(L4>[2]Veriler!$D$4,IF(L4>[2]Veriler!$D$5,IF(L4>[2]Veriler!$D$6,IF(L4>[2]Veriler!$D$7,IF(L4>[2]Veriler!$D$8,"ders sorumlusuna başvur",[2]Veriler!$A$8),[2]Veriler!$A$7),[2]Veriler!$A$6),[2]Veriler!$A$5),[2]Veriler!$A$4),[2]Veriler!$A$3),[2]Veriler!$A$2),[2]Veriler!$A$1) -> 8 | N4: 8 | O4: =VLOOKUP(N4,[2]Veriler!A$1:C$8,2,FALSE) -> 3xOxlip+Rose/Aster | P4: =IF(I4<VLOOKUP(N4,[2]Veriler!A$1:E$8,5,FALSE)," UYGUNDUR","KESİT AKIMI TAŞIYAMIYOR") -> UYGUNDUR
A5: 25 | B5: 25 | C5: 35 | D5: 3 | E5: 45 | F5: =C5*D5*E5 -> 4725 | G5: =0.5*(F5+F6) -> 4725 | H5: =G5/(SQRT(3)*380) -> 7.1788948 | I5: =H5+I6 -> 80.882215 | J5: =I5*C5 -> 2830.8775 | K5: =J5+K6 -> 22296.895 | L5: =K5/(8*35) -> 79.631768 | M5: =IF(L5>[2]Veriler!$D$1,IF(L5>[2]Veriler!$D$2,IF(L5>[2]Veriler!$D$3,IF(L5>[2]Veriler!$D$4,IF(L5>[2]Veriler!$D$5,IF(L5>[2]Veriler!$D$6,IF(L5>[2]Veriler!$D$7,IF(L5>[2]Veriler!$D$8,"ders sorumlusuna başvur",[2]Veriler!$A$8),[2]Veriler!$A$7),[2]Veriler!$A$6),[2]Veriler!$A$5),[2]Veriler!$A$4),[2]Veriler!$A$3),[2]Veriler!$A$2),[2]Veriler!$A$1) -> 7 | N5: 8 | O5: =VLOOKUP(N5,[2]Veriler!A$1:C$8,2,FALSE) -> 3xOxlip+Rose/Aster | P5: =IF(I5<VLOOKUP(N5,[2]Veriler!A$1:E$8,5,FALSE)," UYGUNDUR","KESİT AKIMI TAŞIYAMIYOR") -> UYGUNDUR
A6: 26 | B6: 26 | C6: 35 | D6: 3 | E6: 45 | F6: =C6*D6*E6 -> 4725 | G6: =0.5*(F6+F7) -> 5062.5 | H6: =G6/(SQRT(3)*380) -> 7.691673 | I6: =H6+I7 -> 73.70332 | J6: =I6*C6 -> 2579.6162 | K6: =J6+K7 -> 19466.018 | L6: =K6/(8*35) -> 69.521492 | M6: =IF(L6>[2]Veriler!$D$1,IF(L6>[2]Veriler!$D$2,IF(L6>[2]Veriler!$D$3,IF(L6>[2]Veriler!$D$4,IF(L6>[2]Veriler!$D$5,IF(L6>[2]Veriler!$D$6,IF(L6>[2]Veriler!$D$7,IF(L6>[2]Veriler!$D$8,"ders sorumlusuna başvur",[2]Veriler!$A$8),[2]Veriler!$A$7),[2]Veriler!$A$6),[2]Veriler!$A$5),[2]Veriler!$A$4),[2]Veriler!$A$3),[2]Veriler!$A$2),[2]Veriler!$A$1) -> 7 | N6: 8 | O6: =VLOOKUP(N6,[2]Veriler!A$1:C$8,2,FALSE) -> 3xOxlip+Rose/Aster | P6: =IF(I6<VLOOKUP(N6,[2]Veriler!A$1:E$8,5,FALSE)," UYGUNDUR","KESİT AKIMI TAŞIYAMIYOR") -> UYGUNDUR
A7: 27 | B7: 27 | C7: 40 | D7: 3 | E7: 45 | F7: =C7*D7*E7 -> 5400 | G7: =0.5*(F7+F8+F11) -> 4050 | H7: =G7/(SQRT(3)*380) -> 6.1533384 | I7: =H7+I8 -> 66.011647 | J7: =I7*C7 -> 2640.4659 | K7: =J7+K8 -> 16886.401 | L7: =K7/(8*35) -> 60.308577 | M7: =IF(L7>[2]Veriler!$D$1,IF(L7>[2]Veriler!$D$2,IF(L7>[2]Veriler!$D$3,IF(L7>[2]Veriler!$D$4,IF(L7>[2]Veriler!$D$5,IF(L7>[2]Veriler!$D$6,IF(L7>[2]Veriler!$D$7,IF(L7>[2]Veriler!$D$8,"ders sorumlusuna başvur",[2]Veriler!$A$8),[2]Veriler!$A$7),[2]Veriler!$A$6),[2]Veriler!$A$5),[2]Veriler!$A$4),[2]Veriler!$A$3),[2]Veriler!$A$2),[2]Veriler!$A$1) -> 6 | N7: 8 | O7: =VLOOKUP(N7,[2]Veriler!A$1:C$8,2,FALSE) -> 3xOxlip+Rose/Aster | P7: =IF(I7<VLOOKUP(N7,[2]Veriler!A$1:E$8,5,FALSE)," UYGUNDUR","KESİT AKIMI TAŞIYAMIYOR") -> UYGUNDUR
A8: 28 | B8: 28 | C8: 16 | D8: 2 | E8: 45 | F8: =C8*D8*E8 -> 1440 | G8: =0.5*(F8+F9) -> 2520 | H8: =G8/(SQRT(3)*380) -> 3.8287439 | I8: =H8+I9 -> 59.858309 | J8: =I8*C8 -> 957.73294 | K8: =J8+K9 -> 14245.936 | L8: =K8/(8*35) -> 50.878341 | M8: =IF(L8>[2]Veriler!$D$1,IF(L8>[2]Veriler!$D$2,IF(L8>[2]Veriler!$D$3,IF(L8>[2]Veriler!$D$4,IF(L8>[2]Veriler!$D$5,IF(L8>[2]Veriler!$D$6,IF(L8>[2]Veriler!$D$7,IF(L8>[2]Veriler!$D$8,"ders sorumlusuna başvur",[2]Veriler!$A$8),[2]Veriler!$A$7),[2]Veriler!$A$6),[2]Veriler!$A$5),[2]Veriler!$A$4),[2]Veriler!$A$3),[2]Veriler!$A$2),[2]Veriler!$A$1) -> 5 | N8: 1 | O8: =VLOOKUP(N8,[2]Veriler!A$1:C$8,2,FALSE) -> 5 x Rose | P8: =IF(I8<VLOOKUP(N8,[2]Veriler!A$1:E$8,5,FALSE)," UYGUNDUR","KESİT AKIMI TAŞIYAMIYOR") -> UYGUNDUR
A9: 29 | B9: 29 | C9: 40 | D9: 2 | E9: 45 | F9: =C9*D9*E9 -> 3600 | G9: =0.5*(F9+F10) -> 3600 | H9: =G9/(SQRT(3)*380) -> 5.4696341 | I9: =H9+I10 -> 56.029565 | J9: =I9*C9 -> 2241.1826 | K9: =J9+K10 -> 13288.203 | L9: =K9/(8*35) -> 47.457867 | M9: =IF(L9>[2]Veriler!$D$1,IF(L9>[2]Veriler!$D$2,IF(L9>[2]Veriler!$D$3,IF(L9>[2]Veriler!$D$4,IF(L9>[2]Veriler!$D$5,IF(L9>[2]Veriler!$D$6,IF(L9>[2]Veriler!$D$7,IF(L9>[2]Veriler!$D$8,"ders sorumlusuna başvur",[2]Veriler!$A$8),[2]Veriler!$A$7),[2]Veriler!$A$6),[2]Veriler!$A$5),[2]Veriler!$A$4),[2]Veriler!$A$3),[2]Veriler!$A$2),[2]Veriler!$A$1) -> 5 | N9: 2 | O9: =VLOOKUP(N9,[2]Veriler!A$1:C$8,2,FALSE) -> 3 x Lily + Rose/Lily | P9: =IF(I9<VLOOKUP(N9,[2]Veriler!A$1:E$8,5,FALSE)," UYGUNDUR","KESİT AKIMI TAŞIYAMIYOR") -> UYGUNDUR
A10: 30 | B10: 30 | C10: 40 | D10: 2 | E10: 45 | F10: =C10*D10*E10 -> 3600 | G10: =0.5*(F10) -> 1800 | H10: =G10/(SQRT(3)*380) -> 2.7348171 | I10: =H10+I11 -> 50.55993 | J10: =I10*C10 -> 2022.3972 | K10: =J10+K11 -> 11047.02 | L10: =K10/(8*35) -> 39.453643 | M10: =IF(L10>[2]Veriler!$D$1,IF(L10>[2]Veriler!$D$2,IF(L10>[2]Veriler!$D$3,IF(L10>[2]Veriler!$D$4,IF(L10>[2]Veriler!$D$5,IF(L10>[2]Veriler!$D$6,IF(L10>[2]Veriler!$D$7,IF(L10>[2]Veriler!$D$8,"ders sorumlusuna başvur",[2]Veriler!$A$8),[2]Veriler!$A$7),[2]Veriler!$A$6),[2]Veriler!$A$5),[2]Veriler!$A$4),[2]Veriler!$A$3),[2]Veriler!$A$2),[2]Veriler!$A$1) -> 4 | N10: 1 | O10: =VLOOKUP(N10,[2]Veriler!A$1:C$8,2,FALSE) -> 5 x Rose | P10: =IF(I10<VLOOKUP(N10,[2]Veriler!A$1:E$8,5,FALSE)," UYGUNDUR","KESİT AKIMI TAŞIYAMIYOR") -> UYGUNDUR
A11: 31 | B11: 31 | C11: 14 | D11: 2 | E11: 45 | F11: =C11*D11*E11 -> 1260 | G11: =0.5*(F11+F12+F14) -> 4455 | H11: =G11/(SQRT(3)*380) -> 6.7686722 | I11: =H11+I12 -> 47.825113 | J11: =I11*C11 -> 669.55159 | K11: =J11+K12 -> 9024.6228 | L11: =K11/(8*35) -> 32.230796 | M11: =IF(L11>[2]Veriler!$D$1,IF(L11>[2]Veriler!$D$2,IF(L11>[2]Veriler!$D$3,IF(L11>[2]Veriler!$D$4,IF(L11>[2]Veriler!$D$5,IF(L11>[2]Veriler!$D$6,IF(L11>[2]Veriler!$D$7,IF(L11>[2]Veriler!$D$8,"ders sorumlusuna başvur",[2]Veriler!$A$8),[2]Veriler!$A$7),[2]Veriler!$A$6),[2]Veriler!$A$5),[2]Veriler!$A$4),[2]Veriler!$A$3),[2]Veriler!$A$2),[2]Veriler!$A$1) -> 3 | N11: 2 | O11: =VLOOKUP(N11,[2]Veriler!A$1:C$8,2,FALSE) -> 3 x Lily + Rose/Lily | P11: =IF(I11<VLOOKUP(N11,[2]Veriler!A$1:E$8,5,FALSE)," UYGUNDUR","KESİT AKIMI TAŞIYAMIYOR") -> UYGUNDUR
A12: 32 | B12: 32 | C12: 40 | D12: 2 | E12: 45 | F12: =C12*D12*E12 -> 3600 | G12: =0.5*(F12+F13) -> 3825 | H12: =G12/(SQRT(3)*380) -> 5.8114863 | I12: =H12+I13 -> 41.056441 | J12: =I12*C12 -> 1642.2576 | K12: =J12+K13 -> 8355.0712 | L12: =K12/(8*35) -> 29.83954 | M12: =IF(L12>[2]Veriler!$D$1,IF(L12>[2]Veriler!$D$2,IF(L12>[2]Veriler!$D$3,IF(L12>[2]Veriler!$D$4,IF(L12>[2]Veriler!$D$5,IF(L12>[2]Veriler!$D$6,IF(L12>[2]Veriler!$D$7,IF(L12>[2]Veriler!$D$8,"ders sorumlusuna başvur",[2]Veriler!$A$8),[2]Veriler!$A$7),[2]Veriler!$A$6),[2]Veriler!$A$5),[2]Veriler!$A$4),[2]Veriler!$A$3),[2]Veriler!$A$2),[2]Veriler!$A$1) -> 3 | N12: 1 | O12: =VLOOKUP(N12,[2]Veriler!A$1:C$8,2,FALSE) -> 5 x Rose | P12: =IF(I12<VLOOKUP(N12,[2]Veriler!A$1:E$8,5,FALSE)," UYGUNDUR","KESİT AKIMI TAŞIYAMIYOR") -> UYGUNDUR
A13: 33 | B13: 33 | C13: 40 | D13: 2 | E13: 45 | F13: =C15*D14*E13 -> 4050 | G13: =0.5*(F13) -> 2025 | H13: =G13/(SQRT(3)*380) -> 3.0766692 | I13: =H13+I14 -> 35.244955 | J13: =I13*C13 -> 1409.7982 | K13: =J13+K14 -> 6712.8136 | L13: =K13/(8*35) -> 23.974334 | M13: =IF(L13>[2]Veriler!$D$1,IF(L13>[2]Veriler!$D$2,IF(L13>[2]Veriler!$D$3,IF(L13>[2]Veriler!$D$4,IF(L13>[2]Veriler!$D$5,IF(L13>[2]Veriler!$D$6,IF(L13>[2]Veriler!$D$7,IF(L13>[2]Veriler!$D$8,"ders sorumlusuna başvur",[2]Veriler!$A$8),[2]Veriler!$A$7),[2]Veriler!$A$6),[2]Veriler!$A$5),[2]Veriler!$A$4),[2]Veriler!$A$3),[2]Veriler!$A$2),[2]Veriler!$A$1) -> 2 | N13: 1 | O13: =VLOOKUP(N13,[2]Veriler!A$1:C$8,2,FALSE) -> 5 x Rose | P13: =IF(I13<VLOOKUP(N13,[2]Veriler!A$1:E$8,5,FALSE)," UYGUNDUR","KESİT AKIMI TAŞIYAMIYOR") -> UYGUNDUR
A14: 34 | B14: 34 | C14: 40 | D14: 2 | E14: 45 | F14: =C15*D15*E15 -> 4050 | G14: =0.5*(F14+F15) -> 4050 | H14: =G14/(SQRT(3)*380) -> 6.1533384 | I14: =H14+I15 -> 32.168286 | J14: =I14*C14 -> 1286.7314 | K14: =J14+K15 -> 5303.0154 | L14: =K14/(8*35) -> 18.939341 | M14: =IF(L14>[2]Veriler!$D$1,IF(L14>[2]Veriler!$D$2,IF(L14>[2]Veriler!$D$3,IF(L14>[2]Veriler!$D$4,IF(L14>[2]Veriler!$D$5,IF(L14>[2]Veriler!$D$6,IF(L14>[2]Veriler!$D$7,IF(L14>[2]Veriler!$D$8,"ders sorumlusuna başvur",[2]Veriler!$A$8),[2]Veriler!$A$7),[2]Veriler!$A$6),[2]Veriler!$A$5),[2]Veriler!$A$4),[2]Veriler!$A$3),[2]Veriler!$A$2),[2]Veriler!$A$1) -> 1 | N14: 1 | O14: =VLOOKUP(N14,[2]Veriler!A$1:C$8,2,FALSE) -> 5 x Rose | P14: =IF(I14<VLOOKUP(N14,[2]Veriler!A$1:E$8,5,FALSE)," UYGUNDUR","KESİT AKIMI TAŞIYAMIYOR") -> UYGUNDUR
A15: 35 | B15: 35 | C15: 45 | D15: 2 | E15: 45 | F15: =C15*D15*E15 -> 4050 | G15: =0.5*(F15+F16+F18) -> 3825 | H15: =G15/(SQRT(3)*380) -> 5.8114863 | I15: =H15+I16 -> 26.014947 | J15: =I15*C15 -> 1170.6726 | K15: =J15+K16 -> 4016.284 | L15: =K15/(8*35) -> 14.343871 | M15: =IF(L15>[2]Veriler!$D$1,IF(L15>[2]Veriler!$D$2,IF(L15>[2]Veriler!$D$3,IF(L15>[2]Veriler!$D$4,IF(L15>[2]Veriler!$D$5,IF(L15>[2]Veriler!$D$6,IF(L15>[2]Veriler!$D$7,IF(L15>[2]Veriler!$D$8,"ders sorumlusuna başvur",[2]Veriler!$A$8),[2]Veriler!$A$7),[2]Veriler!$A$6),[2]Veriler!$A$5),[2]Veriler!$A$4),[2]Veriler!$A$3),[2]Veriler!$A$2),[2]Veriler!$A$1) -> 1 | N15: 1 | O15: =VLOOKUP(N15,[2]Veriler!A$1:C$8,2,FALSE) -> 5 x Rose | P15: =IF(I15<VLOOKUP(N15,[2]Veriler!A$1:E$8,5,FALSE)," UYGUNDUR","KESİT AKIMI TAŞIYAMIYOR") -> UYGUNDUR
A16: 36 | B16: 36 | C16: 20 | D16: 2 | E16: 45 | F16: =C16*D16*E16 -> 1800 | G16: =0.5*(F16+F17) -> 2700 | H16: =G16/(SQRT(3)*380) -> 4.1022256 | I16: =H16+I17 -> 20.203461 | J16: =I16*C16 -> 404.06922 | K16: =J16+K17 -> 2845.6113 | L16: =K16/(8*35) -> 10.162898 | M16: =IF(L16>[2]Veriler!$D$1,IF(L16>[2]Veriler!$D$2,IF(L16>[2]Veriler!$D$3,IF(L16>[2]Veriler!$D$4,IF(L16>[2]Veriler!$D$5,IF(L16>[2]Veriler!$D$6,IF(L16>[2]Veriler!$D$7,IF(L16>[2]Veriler!$D$8,"ders sorumlusuna başvur",[2]Veriler!$A$8),[2]Veriler!$A$7),[2]Veriler!$A$6),[2]Veriler!$A$5),[2]Veriler!$A$4),[2]Veriler!$A$3),[2]Veriler!$A$2),[2]Veriler!$A$1) -> 1 | N16: 1 | O16: =VLOOKUP(N16,[2]Veriler!A$1:C$8,2,FALSE) -> 5 x Rose | P16: =IF(I16<VLOOKUP(N16,[2]Veriler!A$1:E$8,5,FALSE)," UYGUNDUR","KESİT AKIMI TAŞIYAMIYOR") -> UYGUNDUR
A17: 37 | B17: 37 | C17: 40 | D17: 2 | E17: 45 | F17: =C17*D17*E17 -> 3600 | G17: =0.5*(F17) -> 1800 | H17: =G17/(SQRT(3)*380) -> 2.7348171 | I17: =H17+I18 -> 16.101235 | J17: =I17*C17 -> 644.04942 | K17: =J17+K18 -> 2441.5421 | L17: =K17/(8*35) -> 8.7197933 | M17: =IF(L17>[2]Veriler!$D$1,IF(L17>[2]Veriler!$D$2,IF(L17>[2]Veriler!$D$3,IF(L17>[2]Veriler!$D$4,IF(L17>[2]Veriler!$D$5,IF(L17>[2]Veriler!$D$6,IF(L17>[2]Veriler!$D$7,IF(L17>[2]Veriler!$D$8,"ders sorumlusuna başvur",[2]Veriler!$A$8),[2]Veriler!$A$7),[2]Veriler!$A$6),[2]Veriler!$A$5),[2]Veriler!$A$4),[2]Veriler!$A$3),[2]Veriler!$A$2),[2]Veriler!$A$1) -> 1 | N17: 1 | O17: =VLOOKUP(N17,[2]Veriler!A$1:C$8,2,FALSE) -> 5 x Rose | P17: =IF(I17<VLOOKUP(N17,[2]Veriler!A$1:E$8,5,FALSE)," UYGUNDUR","KESİT AKIMI TAŞIYAMIYOR") -> UYGUNDUR
A18: 38 | B18: 38 | C18: 40 | D18: 1 | E18: 45 | F18: =C18*D18*E18 -> 1800 | G18: =0.5*(F18+F19+F21) -> 2047.5 | H18: =G18/(SQRT(3)*380) -> 3.1108544 | I18: =H18+I19 -> 13.366418 | J18: =I18*C18 -> 534.65674 | K18: =J18+K19 -> 1797.4927 | L18: =K18/(8*35) -> 6.4196168 | M18: =IF(L18>[2]Veriler!$D$1,IF(L18>[2]Veriler!$D$2,IF(L18>[2]Veriler!$D$3,IF(L18>[2]Veriler!$D$4,IF(L18>[2]Veriler!$D$5,IF(L18>[2]Veriler!$D$6,IF(L18>[2]Veriler!$D$7,IF(L18>[2]Veriler!$D$8,"ders sorumlusuna başvur",[2]Veriler!$A$8),[2]Veriler!$A$7),[2]Veriler!$A$6),[2]Veriler!$A$5),[2]Veriler!$A$4),[2]Veriler!$A$3),[2]Veriler!$A$2),[2]Veriler!$A$1) -> 1 | N18: 1 | O18: =VLOOKUP(N18,[2]Veriler!A$1:C$8,2,FALSE) -> 5 x Rose | P18: =IF(I18<VLOOKUP(N18,[2]Veriler!A$1:E$8,5,FALSE)," UYGUNDUR","KESİT AKIMI TAŞIYAMIYOR") -> UYGUNDUR
A19: 39 | B19: 39 | C19: 11 | D19: 1 | E19: 45 | F19: =C19*D19*E19 -> 495 | G19: =0.5*(F19+F19) -> 495 | H19: =G19/(SQRT(3)*380) -> 0.75207469 | I19: =H19+I20 -> 10.255564 | J19: =I19*C19 -> 112.8112 | K19: =J19+K20 -> 1262.836 | L19: =K19/(8*35) -> 4.5101284 | M19: =IF(L19>[2]Veriler!$D$1,IF(L19>[2]Veriler!$D$2,IF(L19>[2]Veriler!$D$3,IF(L19>[2]Veriler!$D$4,IF(L19>[2]Veriler!$D$5,IF(L19>[2]Veriler!$D$6,IF(L19>[2]Veriler!$D$7,IF(L19>[2]Veriler!$D$8,"ders sorumlusuna başvur",[2]Veriler!$A$8),[2]Veriler!$A$7),[2]Veriler!$A$6),[2]Veriler!$A$5),[2]Veriler!$A$4),[2]Veriler!$A$3),[2]Veriler!$A$2),[2]Veriler!$A$1) -> 1 | N19: 1 | O19: =VLOOKUP(N16,[2]Veriler!A$1:C$8,2,FALSE) -> 5 x Rose | P19: =IF(I19<VLOOKUP(N19,[2]Veriler!A$1:E$8,5,FALSE)," UYGUNDUR","KESİT AKIMI TAŞIYAMIYOR") -> UYGUNDUR
A20: 40 | B20: 40 | C20: 40 | D20: 1 | E20: 45 | F20: =C20*D20*E20 -> 1800 | G20: =0.5*(F20) -> 900 | H20: =G20/(SQRT(3)*380) -> 1.3674085 | I20: =H20+I21 -> 9.5034893 | J20: =I20*C20 -> 380.13957 | K20: =J20+K21 -> 1150.0248 | L20: =K20/(8*35) -> 4.1072313 | M20: =IF(L20>[2]Veriler!$D$1,IF(L20>[2]Veriler!$D$2,IF(L20>[2]Veriler!$D$3,IF(L20>[2]Veriler!$D$4,IF(L20>[2]Veriler!$D$5,IF(L20>[2]Veriler!$D$6,IF(L20>[2]Veriler!$D$7,IF(L20>[2]Veriler!$D$8,"ders sorumlusuna başvur",[2]Veriler!$A$8),[2]Veriler!$A$7),[2]Veriler!$A$6),[2]Veriler!$A$5),[2]Veriler!$A$4),[2]Veriler!$A$3),[2]Veriler!$A$2),[2]Veriler!$A$1) -> 1 | N20: 1 | O20: =VLOOKUP(N17,[2]Veriler!A$1:C$8,2,FALSE) -> 5 x Rose | P20: =IF(I20<VLOOKUP(N20,[2]Veriler!A$1:E$8,5,FALSE)," UYGUNDUR","KESİT AKIMI TAŞIYAMIYOR") -> UYGUNDUR
A21: 41 | B21: 41 | C21: 40 | D21: 1 | E21: 45 | F21: =C21*D21*E21 -> 1800 | G21: =0.5*(F21+F22) -> 1327.5 | H21: =G21/(SQRT(3)*380) -> 2.0169276 | I21: =H21+I22 -> 8.1360808 | J21: =I21*C21 -> 325.44323 | K21: =J21+K22 -> 769.88519 | L21: =K21/(8*35) -> 2.74959 | M21: =IF(L21>[2]Veriler!$D$1,IF(L21>[2]Veriler!$D$2,IF(L21>[2]Veriler!$D$3,IF(L21>[2]Veriler!$D$4,IF(L21>[2]Veriler!$D$5,IF(L21>[2]Veriler!$D$6,IF(L21>[2]Veriler!$D$7,IF(L21>[2]Veriler!$D$8,"ders sorumlusuna başvur",[2]Veriler!$A$8),[2]Veriler!$A$7),[2]Veriler!$A$6),[2]Veriler!$A$5),[2]Veriler!$A$4),[2]Veriler!$A$3),[2]Veriler!$A$2),[2]Veriler!$A$1) -> 1 | N21: 1 | O21: =VLOOKUP(N18,[2]Veriler!A$1:C$8,2,FALSE) -> 5 x Rose | P21: =IF(I21<VLOOKUP(N21,[2]Veriler!A$1:E$8,5,FALSE)," UYGUNDUR","KESİT AKIMI TAŞIYAMIYOR") -> UYGUNDUR
A22: 42 | B22: 42 | C22: 19 | D22: 1 | E22: 45 | F22: =C22*D22*E22 -> 855 | G22: =0.5*(F22+F23) -> 1327.5 | H22: =G22/(SQRT(3)*380) -> 2.0169276 | I22: =H22+I23 -> 6.1191532 | J22: =I22*C22 -> 116.26391 | K22: =J22+K23 -> 444.44196 | L22: =K22/(8*35) -> 1.5872927 | M22: =IF(L22>[2]Veriler!$D$1,IF(L22>[2]Veriler!$D$2,IF(L22>[2]Veriler!$D$3,IF(L22>[2]Veriler!$D$4,IF(L22>[2]Veriler!$D$5,IF(L22>[2]Veriler!$D$6,IF(L22>[2]Veriler!$D$7,IF(L22>[2]Veriler!$D$8,"ders sorumlusuna başvur",[2]Veriler!$A$8),[2]Veriler!$A$7),[2]Veriler!$A$6),[2]Veriler!$A$5),[2]Veriler!$A$4),[2]Veriler!$A$3),[2]Veriler!$A$2),[2]Veriler!$A$1) -> 1 | N22: 1 | O22: =VLOOKUP(N19,[2]Veriler!A$1:C$8,2,FALSE) -> 5 x Rose | P22: =IF(I22<VLOOKUP(N22,[2]Veriler!A$1:E$8,5,FALSE)," UYGUNDUR","KESİT AKIMI TAŞIYAMIYOR") -> UYGUNDUR
A23: 43 | B23: 43 | C23: 40 | D23: 1 | E23: 45 | F23: =C23*D23*E23 -> 1800 | G23: =0.5*(F23+F24) -> 1800 | H23: =G23/(SQRT(3)*380) -> 2.7348171 | I23: =H23+I24 -> 4.1022256 | J23: =I23*C23 -> 164.08902 | K23: =J23+K24 -> 328.17805 | L23: =K23/(8*35) -> 1.1720645 | M23: =IF(L23>[2]Veriler!$D$1,IF(L23>[2]Veriler!$D$2,IF(L23>[2]Veriler!$D$3,IF(L23>[2]Veriler!$D$4,IF(L23>[2]Veriler!$D$5,IF(L23>[2]Veriler!$D$6,IF(L23>[2]Veriler!$D$7,IF(L23>[2]Veriler!$D$8,"ders sorumlusuna başvur",[2]Veriler!$A$8),[2]Veriler!$A$7),[2]Veriler!$A$6),[2]Veriler!$A$5),[2]Veriler!$A$4),[2]Veriler!$A$3),[2]Veriler!$A$2),[2]Veriler!$A$1) -> 1 | N23: 1 | O23: =VLOOKUP(N20,[2]Veriler!A$1:C$8,2,FALSE) -> 5 x Rose | P23: =IF(I23<VLOOKUP(N23,[2]Veriler!A$1:E$8,5,FALSE)," UYGUNDUR","KESİT AKIMI TAŞIYAMIYOR") -> UYGUNDUR
A24: 44 | B24: 44 | C24: 40 | D24: 1 | E24: 45 | F24: =C24*D24*E24 -> 1800 | G24: =0.5*(F24) -> 900 | H24: =G24/(SQRT(3)*380) -> 1.3674085 | I24: =H24 -> 1.3674085 | J24: =I24*C24 -> 54.696341 | K24: 164.08902 | L24: =K24/(8*35) -> 0.58603223 | M24: =IF(L24>[2]Veriler!$D$1,IF(L24>[2]Veriler!$D$2,IF(L24>[2]Veriler!$D$3,IF(L24>[2]Veriler!$D$4,IF(L24>[2]Veriler!$D$5,IF(L24>[2]Veriler!$D$6,IF(L24>[2]Veriler!$D$7,IF(L24>[2]Veriler!$D$8,"ders sorumlusuna başvur",[2]Veriler!$A$8),[2]Veriler!$A$7),[2]Veriler!$A$6),[2]Veriler!$A$5),[2]Veriler!$A$4),[2]Veriler!$A$3),[2]Veriler!$A$2),[2]Veriler!$A$1) -> 1 | N24: 1 | O24: =VLOOKUP(N21,[2]Veriler!A$1:C$8,2,FALSE) -> 5 x Rose | P24: =IF(I24<VLOOKUP(N24,[2]Veriler!A$1:E$8,5,FALSE)," UYGUNDUR","KESİT AKIMI TAŞIYAMIYOR") -> UYGUNDUR
A25: 45 | B25: 45 | C25: 10 | D25: 0 | E25: 45 | F25: =C25*D25*E25 -> 0 | G25: 0 | H25: =G25/(SQRT(3)*380) -> 0 | M25: =IF(L25>[2]Veriler!$D$1,IF(L25>[2]Veriler!$D$2,IF(L25>[2]Veriler!$D$3,IF(L25>[2]Veriler!$D$4,IF(L25>[2]Veriler!$D$5,IF(L25>[2]Veriler!$D$6,IF(L25>[2]Veriler!$D$7,IF(L25>[2]Veriler!$D$8,"ders sorumlusuna başvur",[2]Veriler!$A$8),[2]Veriler!$A$7),[2]Veriler!$A$6),[2]Veriler!$A$5),[2]Veriler!$A$4),[2]Veriler!$A$3),[2]Veriler!$A$2),[2]Veriler!$A$1) -> 1 | N25: 1 | O25: =VLOOKUP(N25,[2]Veriler!A$1:C$8,2,FALSE) -> 5 x Rose | P25: =IF(I25<VLOOKUP(N25,[2]Veriler!A$1:E$8,5,FALSE)," UYGUNDUR","KESİT AKIMI TAŞIYAMIYOR") -> UYGUNDUR
A26: 46 | B26: 46 | C26: 40 | D26: 0 | E26: 45 | F26: =C26*D26*E26 -> 0 | G26: 0 | H26: =G26/(SQRT(3)*380) -> 0 | M26: =IF(L26>[2]Veriler!$D$1,IF(L26>[2]Veriler!$D$2,IF(L26>[2]Veriler!$D$3,IF(L26>[2]Veriler!$D$4,IF(L26>[2]Veriler!$D$5,IF(L26>[2]Veriler!$D$6,IF(L26>[2]Veriler!$D$7,IF(L26>[2]Veriler!$D$8,"ders sorumlusuna başvur",[2]Veriler!$A$8),[2]Veriler!$A$7),[2]Veriler!$A$6),[2]Veriler!$A$5),[2]Veriler!$A$4),[2]Veriler!$A$3),[2]Veriler!$A$2),[2]Veriler!$A$1) -> 1 | N26: 1 | O26: =VLOOKUP(N26,[2]Veriler!A$1:C$8,2,FALSE) -> 5 x Rose | P26: =IF(I26<VLOOKUP(N26,[2]Veriler!A$1:E$8,5,FALSE)," UYGUNDUR","KESİT AKIMI TAŞIYAMIYOR") -> UYGUNDUR
A27: 47 | B27: 47 | C27: 40 | D27: 0 | E27: 45 | F27: =C27*D27*E27 -> 0 | G27: 0 | H27: =G27/(SQRT(3)*380) -> 0 | M27: =IF(L27>[2]Veriler!$D$1,IF(L27>[2]Veriler!$D$2,IF(L27>[2]Veriler!$D$3,IF(L27>[2]Veriler!$D$4,IF(L27>[2]Veriler!$D$5,IF(L27>[2]Veriler!$D$6,IF(L27>[2]Veriler!$D$7,IF(L27>[2]Veriler!$D$8,"ders sorumlusuna başvur",[2]Veriler!$A$8),[2]Veriler!$A$7),[2]Veriler!$A$6),[2]Veriler!$A$5),[2]Veriler!$A$4),[2]Veriler!$A$3),[2]Veriler!$A$2),[2]Veriler!$A$1) -> 1 | N27: 2 | O27: =VLOOKUP(N27,[2]Veriler!A$1:C$8,2,FALSE) -> 3 x Lily + Rose/Lily | P27: =IF(I27<VLOOKUP(N27,[2]Veriler!A$1:E$8,5,FALSE)," UYGUNDUR","KESİT AKIMI TAŞIYAMIYOR") -> UYGUNDUR
A28: 48 | B28: 48 | C28: 40 | D28: 0 | E28: 45 | F28: =C28*D28*E28 -> 0 | G28: 0 | H28: =G28/(SQRT(3)*380) -> 0 | M28: =IF(L28>[2]Veriler!$D$1,IF(L28>[2]Veriler!$D$2,IF(L28>[2]Veriler!$D$3,IF(L28>[2]Veriler!$D$4,IF(L28>[2]Veriler!$D$5,IF(L28>[2]Veriler!$D$6,IF(L28>[2]Veriler!$D$7,IF(L28>[2]Veriler!$D$8,"ders sorumlusuna başvur",[2]Veriler!$A$8),[2]Veriler!$A$7),[2]Veriler!$A$6),[2]Veriler!$A$5),[2]Veriler!$A$4),[2]Veriler!$A$3),[2]Veriler!$A$2),[2]Veriler!$A$1) -> 1 | N28: 1 | O28: =VLOOKUP(N28,[2]Veriler!A$1:C$8,2,FALSE) -> 5 x Rose | P28: =IF(I28<VLOOKUP(N28,[2]Veriler!A$1:E$8,5,FALSE)," UYGUNDUR","KESİT AKIMI TAŞIYAMIYOR") -> UYGUNDUR
A29: 49 | B29: 49 | C29: 40 | D29: 0 | E29: 45 | F29: =C29*D29*E29 -> 0 | G29: 0 | H29: =G29/(SQRT(3)*380) -> 0 | M29: =IF(L29>[2]Veriler!$D$1,IF(L29>[2]Veriler!$D$2,IF(L29>[2]Veriler!$D$3,IF(L29>[2]Veriler!$D$4,IF(L29>[2]Veriler!$D$5,IF(L29>[2]Veriler!$D$6,IF(L29>[2]Veriler!$D$7,IF(L29>[2]Veriler!$D$8,"ders sorumlusuna başvur",[2]Veriler!$A$8),[2]Veriler!$A$7),[2]Veriler!$A$6),[2]Veriler!$A$5),[2]Veriler!$A$4),[2]Veriler!$A$3),[2]Veriler!$A$2),[2]Veriler!$A$1) -> 1 | N29: 1 | O29: =VLOOKUP(N29,[2]Veriler!A$1:C$8,2,FALSE) -> 5 x Rose | P29: =IF(I29<VLOOKUP(N29,[2]Veriler!A$1:E$8,5,FALSE)," UYGUNDUR","KESİT AKIMI TAŞIYAMIYOR") -> UYGUNDUR
A30: 50 | B30: 50 | C30: 17 | D30: 0 | E30: 45 | F30: =C30*D30*E30 -> 0 | G30: 0 | H30: =G30/(SQRT(3)*380) -> 0 | M30: =IF(L30>[2]Veriler!$D$1,IF(L30>[2]Veriler!$D$2,IF(L30>[2]Veriler!$D$3,IF(L30>[2]Veriler!$D$4,IF(L30>[2]Veriler!$D$5,IF(L30>[2]Veriler!$D$6,IF(L30>[2]Veriler!$D$7,IF(L30>[2]Veriler!$D$8,"ders sorumlusuna başvur",[2]Veriler!$A$8),[2]Veriler!$A$7),[2]Veriler!$A$6),[2]Veriler!$A$5),[2]Veriler!$A$4),[2]Veriler!$A$3),[2]Veriler!$A$2),[2]Veriler!$A$1) -> 1 | N30: 1 | O30: =VLOOKUP(N30,[2]Veriler!A$1:C$8,2,FALSE) -> 5 x Rose | P30: =IF(I30<VLOOKUP(N30,[2]Veriler!A$1:E$8,5,FALSE)," UYGUNDUR","KESİT AKIMI TAŞIYAMIYOR") -> UYGUNDUR
A31: 51 | B31: 51 | C31: 30 | D31: 0 | E31: 45 | F31: =C31*D31*E31 -> 0 | G31: 0 | H31: =G31/(SQRT(3)*380) -> 0 | M31: =IF(L31>[2]Veriler!$D$1,IF(L31>[2]Veriler!$D$2,IF(L31>[2]Veriler!$D$3,IF(L31>[2]Veriler!$D$4,IF(L31>[2]Veriler!$D$5,IF(L31>[2]Veriler!$D$6,IF(L31>[2]Veriler!$D$7,IF(L31>[2]Veriler!$D$8,"ders sorumlusuna başvur",[2]Veriler!$A$8),[2]Veriler!$A$7),[2]Veriler!$A$6),[2]Veriler!$A$5),[2]Veriler!$A$4),[2]Veriler!$A$3),[2]Veriler!$A$2),[2]Veriler!$A$1) -> 1 | N31: 1 | O31: =VLOOKUP(N31,[2]Veriler!A$1:C$8,2,FALSE) -> 5 x Rose | P31: =IF(I31<VLOOKUP(N31,[2]Veriler!A$1:E$8,5,FALSE)," UYGUNDUR","KESİT AKIMI TAŞIYAMIYOR") -> UYGUNDUR
A32: 52 | B32: 52 | C32: 40 | D32: 0 | E32: 45 | F32: =C32*D32*E32 -> 0 | G32: 0 | H32: =G32/(SQRT(3)*380) -> 0 | M32: =IF(L32>[2]Veriler!$D$1,IF(L32>[2]Veriler!$D$2,IF(L32>[2]Veriler!$D$3,IF(L32>[2]Veriler!$D$4,IF(L32>[2]Veriler!$D$5,IF(L32>[2]Veriler!$D$6,IF(L32>[2]Veriler!$D$7,IF(L32>[2]Veriler!$D$8,"ders sorumlusuna başvur",[2]Veriler!$A$8),[2]Veriler!$A$7),[2]Veriler!$A$6),[2]Veriler!$A$5),[2]Veriler!$A$4),[2]Veriler!$A$3),[2]Veriler!$A$2),[2]Veriler!$A$1) -> 1 | N32: 1 | O32: =VLOOKUP(N32,[2]Veriler!A$1:C$8,2,FALSE) -> 5 x Rose | P32: =IF(I32<VLOOKUP(N32,[2]Veriler!A$1:E$8,5,FALSE)," UYGUNDUR","KESİT AKIMI TAŞIYAMIYOR") -> UYGUNDUR
A33: 53 | B33: 53 | C33: 40 | D33: 0 | E33: 45 | F33: =C33*D33*E33 -> 0 | G33: 0 | H33: =G33/(SQRT(3)*380) -> 0 | M33: =IF(L33>[2]Veriler!$D$1,IF(L33>[2]Veriler!$D$2,IF(L33>[2]Veriler!$D$3,IF(L33>[2]Veriler!$D$4,IF(L33>[2]Veriler!$D$5,IF(L33>[2]Veriler!$D$6,IF(L33>[2]Veriler!$D$7,IF(L33>[2]Veriler!$D$8,"ders sorumlusuna başvur",[2]Veriler!$A$8),[2]Veriler!$A$7),[2]Veriler!$A$6),[2]Veriler!$A$5),[2]Veriler!$A$4),[2]Veriler!$A$3),[2]Veriler!$A$2),[2]Veriler!$A$1) -> 1 | N33: 1 | O33: =VLOOKUP(N33,[2]Veriler!A$1:C$8,2,FALSE) -> 5 x Rose | P33: =IF(I33<VLOOKUP(N33,[2]Veriler!A$1:E$8,5,FALSE)," UYGUNDUR","KESİT AKIMI TAŞIYAMIYOR") -> UYGUNDUR
A34: 54 | B34: 54 | C34: 40 | D34: 0 | E34: 45 | F34: =C34*D34*E34 -> 0 | G34: 0 | H34: =G34/(SQRT(3)*380) -> 0 | M34: =IF(L34>[2]Veriler!$D$1,IF(L34>[2]Veriler!$D$2,IF(L34>[2]Veriler!$D$3,IF(L34>[2]Veriler!$D$4,IF(L34>[2]Veriler!$D$5,IF(L34>[2]Veriler!$D$6,IF(L34>[2]Veriler!$D$7,IF(L34>[2]Veriler!$D$8,"ders sorumlusuna başvur",[2]Veriler!$A$8),[2]Veriler!$A$7),[2]Veriler!$A$6),[2]Veriler!$A$5),[2]Veriler!$A$4),[2]Veriler!$A$3),[2]Veriler!$A$2),[2]Veriler!$A$1) -> 1 | N34: 1 | O34: =VLOOKUP(N34,[2]Veriler!A$1:C$8,2,FALSE) -> 5 x Rose | P34: =IF(I34<VLOOKUP(N34,[2]Veriler!A$1:E$8,5,FALSE)," UYGUNDUR","KESİT AKIMI TAŞIYAMIYOR") -> UYGUNDUR
A35: 55 | B35: 55 | C35: 40 | D35: 0 | E35: 45 | F35: =C35*D35*E35 -> 0 | G35: 0 | H35: =G35/(SQRT(3)*380) -> 0 | M35: =IF(L35>[2]Veriler!$D$1,IF(L35>[2]Veriler!$D$2,IF(L35>[2]Veriler!$D$3,IF(L35>[2]Veriler!$D$4,IF(L35>[2]Veriler!$D$5,IF(L35>[2]Veriler!$D$6,IF(L35>[2]Veriler!$D$7,IF(L35>[2]Veriler!$D$8,"ders sorumlusuna başvur",[2]Veriler!$A$8),[2]Veriler!$A$7),[2]Veriler!$A$6),[2]Veriler!$A$5),[2]Veriler!$A$4),[2]Veriler!$A$3),[2]Veriler!$A$2),[2]Veriler!$A$1) -> 1 | N35: 1 | O35: =VLOOKUP(N32,[2]Veriler!A$1:C$8,2,FALSE) -> 5 x Rose | P35: =IF(I35<VLOOKUP(N35,[2]Veriler!A$1:E$8,5,FALSE)," UYGUNDUR","KESİT AKIMI TAŞIYAMIYOR") -> UYGUNDUR
A36: 56 | B36: 56 | C36: 40 | D36: 0 | E36: 45 | F36: =C36*D36*E36 -> 0 | G36: 0 | H36: =G36/(SQRT(3)*380) -> 0 | M36: =IF(L36>[2]Veriler!$D$1,IF(L36>[2]Veriler!$D$2,IF(L36>[2]Veriler!$D$3,IF(L36>[2]Veriler!$D$4,IF(L36>[2]Veriler!$D$5,IF(L36>[2]Veriler!$D$6,IF(L36>[2]Veriler!$D$7,IF(L36>[2]Veriler!$D$8,"ders sorumlusuna başvur",[2]Veriler!$A$8),[2]Veriler!$A$7),[2]Veriler!$A$6),[2]Veriler!$A$5),[2]Veriler!$A$4),[2]Veriler!$A$3),[2]Veriler!$A$2),[2]Veriler!$A$1) -> 1 | N36: 1 | O36: =VLOOKUP(N33,[2]Veriler!A$1:C$8,2,FALSE) -> 5 x Rose | P36: =IF(I36<VLOOKUP(N36,[2]Veriler!A$1:E$8,5,FALSE)," UYGUNDUR","KESİT AKIMI TAŞIYAMIYOR") -> UYGUNDUR
A37: 57 | B37: 57 | C37: 40 | D37: 0 | E37: 45 | F37: =C37*D37*E37 -> 0 | G37: 0 | H37: =G37/(SQRT(3)*380) -> 0 | M37: =IF(L37>[2]Veriler!$D$1,IF(L37>[2]Veriler!$D$2,IF(L37>[2]Veriler!$D$3,IF(L37>[2]Veriler!$D$4,IF(L37>[2]Veriler!$D$5,IF(L37>[2]Veriler!$D$6,IF(L37>[2]Veriler!$D$7,IF(L37>[2]Veriler!$D$8,"ders sorumlusuna başvur",[2]Veriler!$A$8),[2]Veriler!$A$7),[2]Veriler!$A$6),[2]Veriler!$A$5),[2]Veriler!$A$4),[2]Veriler!$A$3),[2]Veriler!$A$2),[2]Veriler!$A$1) -> 1 | N37: 1 | O37: =VLOOKUP(N34,[2]Veriler!A$1:C$8,2,FALSE) -> 5 x Rose | P37: =IF(I37<VLOOKUP(N37,[2]Veriler!A$1:E$8,5,FALSE)," UYGUNDUR","KESİT AKIMI TAŞIYAMIYOR") -> UYGUNDUR
A38: 58 | B38: 58 | C38: 40 | D38: 0 | E38: 45 | F38: =C38*D38*E38 -> 0 | G38: 0 | H38: =G38/(SQRT(3)*380) -> 0 | M38: =IF(L38>[2]Veriler!$D$1,IF(L38>[2]Veriler!$D$2,IF(L38>[2]Veriler!$D$3,IF(L38>[2]Veriler!$D$4,IF(L38>[2]Veriler!$D$5,IF(L38>[2]Veriler!$D$6,IF(L38>[2]Veriler!$D$7,IF(L38>[2]Veriler!$D$8,"ders sorumlusuna başvur",[2]Veriler!$A$8),[2]Veriler!$A$7),[2]Veriler!$A$6),[2]Veriler!$A$5),[2]Veriler!$A$4),[2]Veriler!$A$3),[2]Veriler!$A$2),[2]Veriler!$A$1) -> 1 | N38: 1 | O38: =VLOOKUP(N35,[2]Veriler!A$1:C$8,2,FALSE) -> 5 x Rose | P38: =IF(I38<VLOOKUP(N38,[2]Veriler!A$1:E$8,5,FALSE)," UYGUNDUR","KESİT AKIMI TAŞIYAMIYOR") -> UYGUNDUR
A39: 59 | B39: 59 | C39: 40 | D39: 0 | E39: 45 | F39: =C39*D39*E39 -> 0 | G39: 0 | H39: =G39/(SQRT(3)*380) -> 0 | M39: =IF(L39>[2]Veriler!$D$1,IF(L39>[2]Veriler!$D$2,IF(L39>[2]Veriler!$D$3,IF(L39>[2]Veriler!$D$4,IF(L39>[2]Veriler!$D$5,IF(L39>[2]Veriler!$D$6,IF(L39>[2]Veriler!$D$7,IF(L39>[2]Veriler!$D$8,"ders sorumlusuna başvur",[2]Veriler!$A$8),[2]Veriler!$A$7),[2]Veriler!$A$6),[2]Veriler!$A$5),[2]Veriler!$A$4),[2]Veriler!$A$3),[2]Veriler!$A$2),[2]Veriler!$A$1) -> 1 | N39: 1 | O39: =VLOOKUP(N36,[2]Veriler!A$1:C$8,2,FALSE) -> 5 x Rose | P39: =IF(I39<VLOOKUP(N39,[2]Veriler!A$1:E$8,5,FALSE)," UYGUNDUR","KESİT AKIMI TAŞIYAMIYOR") -> UYGUNDUR
A40: 60 | B40: 60 | C40: 31 | D40: 0 | E40: 45 | F40: =C40*D40*E40 -> 0 | G40: 0 | H40: =G40/(SQRT(3)*380) -> 0 | M40: =IF(L40>[2]Veriler!$D$1,IF(L40>[2]Veriler!$D$2,IF(L40>[2]Veriler!$D$3,IF(L40>[2]Veriler!$D$4,IF(L40>[2]Veriler!$D$5,IF(L40>[2]Veriler!$D$6,IF(L40>[2]Veriler!$D$7,IF(L40>[2]Veriler!$D$8,"ders sorumlusuna başvur",[2]Veriler!$A$8),[2]Veriler!$A$7),[2]Veriler!$A$6),[2]Veriler!$A$5),[2]Veriler!$A$4),[2]Veriler!$A$3),[2]Veriler!$A$2),[2]Veriler!$A$1) -> 1 | N40: 1 | O40: =VLOOKUP(N37,[2]Veriler!A$1:C$8,2,FALSE) -> 5 x Rose | P40: =IF(I40<VLOOKUP(N40,[2]Veriler!A$1:E$8,5,FALSE)," UYGUNDUR","KESİT AKIMI TAŞIYAMIYOR") -> UYGUNDUR
...

Sheet 5TR1_2 Abone
A1: AKTİF GÜÇ
A2: Branşman Noktasına İrca Edilen Yük | C2: 17.5 | E2: 100 | G2: 175.5 | I2: 129.5 | K2: 122.5 | M2: 129.5 | O2: 69.5
A3: Hat Yükleri (m) | B3: =D3+C2 -> 744 | D3: =F3+E2 -> 726.5 | F3: =H3+G2 -> 626.5 | H3: =J3+I2 -> 451 | J3: =L3+K2 -> 321.5 | L3: =N3+M2 -> 199 | N3: 69.5
A4: Güç Yoğunluğu (J) | B4: 45 | D4: 45 | F4: 45 | H4: 45 | J4: 45 | L4: 45 | N4: 45
A5: Ktri | B5: 7.75 | D5: 1.84 | F5: 1.84 | H5: 7.42 | J5: 9.36 | L5: 9.36 | N5: 9.36
A6: %e | B6: =B5*B4*B3*10^-7*10 -> 0.25947 | D6: =D5*D4*D3*10^-7*35 -> 0.2105397 | F6: =F5*F4*F3*10^-7*145 -> 0.7521759 | H6: =H5*H4*H3*10^-7*14 -> 0.21082446 | J6: =J5*J4*J3*10^-7*85 -> 1.1510343 | L6: =L5*L4*L3*10^-7*40 -> 0.3352752 | N6: =N5*N4*N3*10^-7*139 -> 0.40690026
B7: Toplam %e = 3.32522082 < 5 uygundur

Sheet 5TR1_2 Aydınlatma
A1: AKTİF GÜÇ
A2: Branşman Noktasına İrca Edilen Yük | B2: 125 | C2: 1875 | D2: 1000 | E2: 125 | F2: 125 | G2: 125 | H2: 125 | I2: 125 | J2: 125 | K2: 125 | L2: 125 | M2: 125 | N2: 125 | O2: 125 | P2: 125 | Q2: 125 | R2: 125 | S2: 125 | T2: 125 | U2: 125
A3: Hat Yükleri (m) | B3: 6125 | C3: 6000 | D3: 4125 | E3: 3125 | F3: 2000 | G3: 1875 | H3: 1750 | I3: 1625 | J3: 1500 | K3: 1375 | L3: 1250 | M3: 1125 | N3: 1000 | O3: 875 | P3: 750 | Q3: 625 | R3: 500 | S3: 375 | T3: 250 | U3: 125
A4: Kmono
A5: %e

Sheet 5TR1_2 Moment 
A1: Moment | B1: Toplam Moment | C1: Kesit | D1: Önerilen Hat tertibi | E1: Tercih edilen Hat tertibi | F1: Hat Seçimi | G1: Isıya göre kontrol
A3: 3333.4001 | B3: 28712.434 | C3: 102.54441 | D3: 8 | E3: 8 | F3: 3xOxlip+Rose/Aster | G3: UYGUNDUR
A4: 3082.1388 | B4: 25379.034 | C4: 90.639407 | D4: 8 | E4: 8 | F4: 3xOxlip+Rose/Aster | G4: UYGUNDUR
A5: 2830.8775 | B5: 22296.895 | C5: 79.631768 | D5: 7 | E5: 8 | F5: 3xOxlip+Rose/Aster | G5: UYGUNDUR
A6: 2579.6162 | B6: 19466.018 | C6: 69.521492 | D6: 7 | E6: 8 | F6: 3xOxlip+Rose/Aster | G6: UYGUNDUR
A7: 2640.4659 | B7: 16886.401 | C7: 60.308577 | D7: 6 | E7: 8 | F7: 3xOxlip+Rose/Aster | G7: UYGUNDUR
A8: 957.73294 | B8: 14245.936 | C8: 50.878341 | D8: 5 | E8: 1 | F8: 5 x Rose | G8: UYGUNDUR
A9: 2241.1826 | B9: 13288.203 | C9: 47.457867 | D9: 5 | E9: 2 | F9: 3 x Lily + Rose/Lily | G9: UYGUNDUR
A10: 2022.3972 | B10: 11047.02 | C10: 39.453643 | D10: 4 | E10: 1 | F10: 5 x Rose | G10: UYGUNDUR
A11: 669.55159 | B11: 9024.6228 | C11: 32.230796 | D11: 3 | E11: 2 | F11: 3 x Lily + Rose/Lily | G11: UYGUNDUR
A12: 1642.2576 | B12: 8355.0712 | C12: 29.83954 | D12: 3 | E12: 1 | F12: 5 x Rose | G12: UYGUNDUR
A13: 1409.7982 | B13: 6712.8136 | C13: 23.974334 | D13: 2 | E13: 1 | F13: 5 x Rose | G13: UYGUNDUR
A14: 1286.7314 | B14: 5303.0154 | C14: 18.939341 | D14: 1 | E14: 1 | F14: 5 x Rose | G14: UYGUNDUR
... A24: 54.696341 | B24: 164.08902 | C24: 0.58603223 | D24: 1 | E24: 1 | F24: 5 x Rose | G24: UYGUNDUR
D25: 1 | E25: 1 | F25: 5 x Rose | G25: UYGUNDUR
D26: 1 | E26: 1 | F26: 5 x Rose | G26: UYGUNDUR
D27: 1 | E27: 2 | F27: 3 x Lily + Rose/Lily | G27: UYGUNDUR
D28: 1 | E28: 1 | F28: 5 x Rose | G28: UYGUNDUR
D29: 1 | E29: 1 | F29: 5 x Rose | G29: UYGUNDUR
D30: 1 | E30: 1 | F30: 5 x Rose | G30: UYGUNDUR
D31: 1 | E31: 1 | F31: 5 x Rose | G31: UYGUNDUR
D32: 1 | E32: 1 | F32: 5 x Rose | G32: UYGUNDUR
D33: 1 | E33: 1 | F33: 5 x Rose | G33: UYGUNDUR
D34: 1 | E34: 1 | F34: 5 x Rose | G34: UYGUNDUR
D35: 1 | E35: 1 | F35: 5 x Rose | G35: UYGUNDUR
D36: 1 | E36: 1 | F36: 5 x Rose | G36: UYGUNDUR
... D49: 1 | E49: 1 | F49: 5 x Rose | G49: UYGUNDUR

Sheet 5TR1_3 Gücü ve Akım
A1: Direk No | B1: Hat No | C1: Mesafe | D1: Kat Sayısı | E1: Güç Yoğunluğu | F1: Hat Gücü | G1: Direk Gücü | H1: Direk Akımı | I1: Hat Akımı | J1: Moment | K1: Toplam Moment | L1: Kesit | M1: Önerilen Hat tertibi | N1: Tercih edilen Hat tertibi | O1: Hat Seçimi | P1: Isıya göre kontrol
A2: TR1_3 | G2: =0.5*(F3) -> 1687.5 | H2: =G2/(SQRT(3)*380) -> 2.563891
A3: 70 | B3: 70 | C3: 25 | D3: 3 | E3: 45 | F3: =C3*D3*E3 -> 3375 | G3: =0.5*(F3+F4) -> 3375 | H3: =G3/(SQRT(3)*380) -> 5.127782 | I3: =H3+I4 -> 156.87594 | J3: =I3*C3 -> 3921.8986 | K3: =J3+K4 -> 18915.807 | L3: =K3/(8*35) -> 67.556453 | M3: =IF(L3>Veriler!$D$1,IF(L3>Veriler!$D$2,IF(L3>Veriler!$D$3,IF(L3>Veriler!$D$4,IF(L3>Veriler!$D$5,IF(L3>Veriler!$D$6,IF(L3>Veriler!$D$7,IF(L3>Veriler!$D$8,"ders sorumlusuna başvur",Veriler!$A$8),Veriler!$A$7),Veriler!$A$6),Veriler!$A$5),Veriler!$A$4),Veriler!$A$3),Veriler!$A$2),Veriler!$A$1) -> 7 | N3: 7 | O3: =VLOOKUP(N3,Veriler!A$1:C$8,2,FALSE) -> 3xPhlox + Rose/Poppy | P3: =IF(I4<VLOOKUP(N4,Veriler!A$1:E$8,5,FALSE)," UYGUNDUR","KESİT AKIMI TAŞIYAMIYOR") -> UYGUNDUR
A4: 71 | B4: 71 | C4: 25 | D4: 3 | E4: 45 | F4: =C4*D4*E4 -> 3375 | G4: =0.5*(F4+F5+F23) -> 5872.5 | H4: =G4/(SQRT(3)*380) -> 8.9223407 | I4: =H4+H5+H6+H7+H8+H9+H10+H11+H12+H13+H14+H15+H16+H17+H18+H19+H20+H21+H22+I23 -> 151.74816 | J4: =I4*C4 -> 3793.7041 | K4: =J4+K23 -> 14993.908 | L4: =K4/(8*35) -> 53.549672 | M4: =IF(L4>Veriler!$D$1,IF(L4>Veriler!$D$2,IF(L4>Veriler!$D$3,IF(L4>Veriler!$D$4,IF(L4>Veriler!$D$5,IF(L4>Veriler!$D$6,IF(L4>Veriler!$D$7,IF(L4>Veriler!$D$8,"ders sorumlusuna başvur",Veriler!$A$8),Veriler!$A$7),Veriler!$A$6),Veriler!$A$5),Veriler!$A$4),Veriler!$A$3),Veriler!$A$2),Veriler!$A$1) -> 6 | N4: 7 | O4: =VLOOKUP(N4,Veriler!A$1:C$8,2,FALSE) -> 3xPhlox + Rose/Poppy | P4: =IF(I4<VLOOKUP(N4,Veriler!A$1:E$8,5,FALSE)," UYGUNDUR","KESİT AKIMI TAŞIYAMIYOR") -> UYGUNDUR
A5: 72 | B5: 72 | C5: 40 | D5: 3 | E5: 45 | F5: =C5*D5*E5 -> 5400 | G5: =0.5*(F5+F6) -> 5400 | H5: =G5/(SQRT(3)*380) -> 8.2044512 | M5: =IF(L5>Veriler!$D$1,IF(L5>Veriler!$D$2,IF(L5>Veriler!$D$3,IF(L5>Veriler!$D$4,IF(L5>Veriler!$D$5,IF(L5>Veriler!$D$6,IF(L5>Veriler!$D$7,IF(L5>Veriler!$D$8,"ders sorumlusuna başvur",Veriler!$A$8),Veriler!$A$7),Veriler!$A$6),Veriler!$A$5),Veriler!$A$4),Veriler!$A$3),Veriler!$A$2),Veriler!$A$1) -> 1 | N5: 1 | O5: =VLOOKUP(N5,Veriler!A$1:C$8,2,FALSE) -> 5 x Rose | P5: =IF(I5<VLOOKUP(N5,Veriler!A$1:E$8,5,FALSE)," UYGUNDUR","KESİT AKIMI TAŞIYAMIYOR") -> UYGUNDUR
A6: 73 | B6: 73 | C6: 40 | D6: 3 | E6: 45 | F6: =C6*D6*E6 -> 5400 | G6: =0.5*(F6+F7) -> 4252.5 | H6: =G6/(SQRT(3)*380) -> 6.4610053 | M6: =IF(L6>Veriler!$D$1,IF(L6>Veriler!$D$2,IF(L6>Veriler!$D$3,IF(L6>Veriler!$D$4,IF(L6>Veriler!$D$5,IF(L6>Veriler!$D$6,IF(L6>Veriler!$D$7,IF(L6>Veriler!$D$8,"ders sorumlusuna başvur",Veriler!$A$8),Veriler!$A$7),Veriler!$A$6),Veriler!$A$5),Veriler!$A$4),Veriler!$A$3),Veriler!$A$2),Veriler!$A$1) -> 1 | N6: 1 | O6: =VLOOKUP(N6,Veriler!A$1:C$8,2,FALSE) -> 5 x Rose | P6: =IF(I6<VLOOKUP(N6,Veriler!A$1:E$8,5,FALSE)," UYGUNDUR","KESİT AKIMI TAŞIYAMIYOR") -> UYGUNDUR
A7: 74 | B7: 74 | C7: 23 | D7: 3 | E7: 45 | F7: =C7*D7*E7 -> 3105 | G7: =0.5*(F7+F8+F12) -> 4590 | H7: =G7/(SQRT(3)*380) -> 6.9737835 | M7: =IF(L7>Veriler!$D$1,IF(L7>Veriler!$D$2,IF(L7>Veriler!$D$3,IF(L7>Veriler!$D$4,IF(L7>Veriler!$D$5,IF(L7>Veriler!$D$6,IF(L7>Veriler!$D$7,IF(L7>Veriler!$D$8,"ders sorumlusuna başvur",Veriler!$A$8),Veriler!$A$7),Veriler!$A$6),Veriler!$A$5),Veriler!$A$4),Veriler!$A$3),Veriler!$A$2),Veriler!$A$1) -> 1 | N7: 1 | O7: =VLOOKUP(N7,Veriler!A$1:C$8,2,FALSE) -> 5 x Rose | P7: =IF(I7<VLOOKUP(N7,Veriler!A$1:E$8,5,FALSE)," UYGUNDUR","KESİT AKIMI TAŞIYAMIYOR") -> UYGUNDUR
A8: 75 | B8: 75 | C8: 29 | D8: 3 | E8: 45 | F8: =C8*D8*E8 -> 3915 | G8: =0.5*(F8+F10) -> 3915 | H8: =G8/(SQRT(3)*380) -> 5.9482271 | M8: =IF(L8>Veriler!$D$1,IF(L8>Veriler!$D$2,IF(L8>Veriler!$D$3,IF(L8>Veriler!$D$4,IF(L8>Veriler!$D$5,IF(L8>Veriler!$D$6,IF(L8>Veriler!$D$7,IF(L8>Veriler!$D$8,"ders sorumlusuna başvur",Veriler!$A$8),Veriler!$A$7),Veriler!$A$6),Veriler!$A$5),Veriler!$A$4),Veriler!$A$3),Veriler!$A$2),Veriler!$A$1) -> 1 | N8: 1 | O8: =VLOOKUP(N8,Veriler!A$1:C$8,2,FALSE) -> 5 x Rose | P8: =IF(I8<VLOOKUP(N8,Veriler!A$1:E$8,5,FALSE)," UYGUNDUR","KESİT AKIMI TAŞIYAMIYOR") -> UYGUNDUR
A9: 76 | B9: 76 | C9: 29 | D9: 3 | E9: 45 | F9: =C9*D9*E9 -> 3915 | G9: =0.5*(F9+F10) -> 3915 | H9: =G9/(SQRT(3)*380) -> 5.9482271 | M9: =IF(L9>Veriler!$D$1,IF(L9>Veriler!$D$2,IF(L9>Veriler!$D$3,IF(L9>Veriler!$D$4,IF(L9>Veriler!$D$5,IF(L9>Veriler!$D$6,IF(L9>Veriler!$D$7,IF(L9>Veriler!$D$8,"ders sorumlusuna başvur",Veriler!$A$8),Veriler!$A$7),Veriler!$A$6),Veriler!$A$5),Veriler!$A$4),Veriler!$A$3),Veriler!$A$2),Veriler!$A$1) -> 1 | N9: 1 | O9: =VLOOKUP(N9,Veriler!A$1:C$8,2,FALSE) -> 5 x Rose | P9: =IF(I9<VLOOKUP(N9,Veriler!A$1:E$8,5,FALSE)," UYGUNDUR","KESİT AKIMI TAŞIYAMIYOR") -> UYGUNDUR
A10: 77 | B10: 77 | C10: 29 | D10: 3 | E10: 45 | F10: =C10*D10*E10 -> 3915 | G10: =0.5*(F10+F11) -> 3915 | H10: =G10/(SQRT(3)*380) -> 5.9482271 | M10: =IF(L10>Veriler!$D$1,IF(L10>Veriler!$D$2,IF(L10>Veriler!$D$3,IF(L10>Veriler!$D$4,IF(L10>Veriler!$D$5,IF(L10>Veriler!$D$6,IF(L10>Veriler!$D$7,IF(L10>Veriler!$D$8,"ders sorumlusuna başvur",Veriler!$A$8),Veriler!$A$7),Veriler!$A$6),Veriler!$A$5),Veriler!$A$4),Veriler!$A$3),Veriler!$A$2),Veriler!$A$1) -> 1 | N10: 1 | O10: =VLOOKUP(N10,Veriler!A$1:C$8,2,FALSE) -> 5 x Rose | P10: =IF(I10<VLOOKUP(N10,Veriler!A$1:E$8,5,FALSE)," UYGUNDUR","KESİT AKIMI TAŞIYAMIYOR") -> UYGUNDUR
A11: 78 | B11: 78 | C11: 29 | D11: 3 | E11: 45 | F11: =C11*D11*E11 -> 3915 | G11: =0.5*(F11) -> 1957.5 | H11: =G11/(SQRT(3)*380) -> 2.9741136 | M11: =IF(L11>Veriler!$D$1,IF(L11>Veriler!$D$2,IF(L11>Veriler!$D$3,IF(L11>Veriler!$D$4,IF(L11>Veriler!$D$5,IF(L11>Veriler!$D$6,IF(L11>Veriler!$D$7,IF(L11>Veriler!$D$8,"ders sorumlusuna başvur",Veriler!$A$8),Veriler!$A$7),Veriler!$A$6),Veriler!$A$5),Veriler!$A$4),Veriler!$A$3),Veriler!$A$2),Veriler!$A$1) -> 1 | N11: 1 | O11: =VLOOKUP(N11,Veriler!A$1:C$8,2,FALSE) -> 5 x Rose | P11: =IF(I11<VLOOKUP(N11,Veriler!A$1:E$8,5,FALSE)," UYGUNDUR","KESİT AKIMI TAŞIYAMIYOR") -> UYGUNDUR
A12: 79 | B12: 79 | C12: 16 | D12: 3 | E12: 45 | F12: =C12*D12*E12 -> 2160 | G12: =0.5*(F12+F13) -> 2835 | H12: =G12/(SQRT(3)*380) -> 4.3073369 | M12: =IF(L12>Veriler!$D$1,IF(L12>Veriler!$D$2,IF(L12>Veriler!$D$3,IF(L12>Veriler!$D$4,IF(L12>Veriler!$D$5,IF(L12>Veriler!$D$6,IF(L12>Veriler!$D$7,IF(L12>Veriler!$D$8,"ders sorumlusuna başvur",Veriler!$A$8),Veriler!$A$7),Veriler!$A$6),Veriler!$A$5),Veriler!$A$4),Veriler!$A$3),Veriler!$A$2),Veriler!$A$1) -> 1 | N12: 1 | O12: =VLOOKUP(N12,Veriler!A$1:C$8,2,FALSE) -> 5 x Rose | P12: =IF(I12<VLOOKUP(N12,Veriler!A$1:E$8,5,FALSE)," UYGUNDUR","KESİT AKIMI TAŞIYAMIYOR") -> UYGUNDUR
A13: 80 | B13: 80 | C13: 26 | D13: 3 | E13: 45 | F13: =C13*D13*E13 -> 3510 | G13: =0.5*(F13+F14) -> 3510 | H13: =G13/(SQRT(3)*380) -> 5.3328933 | M13: =IF(L13>Veriler!$D$1,IF(L13>Veriler!$D$2,IF(L13>Veriler!$D$3,IF(L13>Veriler!$D$4,IF(L13>Veriler!$D$5,IF(L13>Veriler!$D$6,IF(L13>Veriler!$D$7,IF(L13>Veriler!$D$8,"ders sorumlusuna başvur",Veriler!$A$8),Veriler!$A$7),Veriler!$A$6),Veriler!$A$5),Veriler!$A$4),Veriler!$A$3),Veriler!$A$2),Veriler!$A$1) -> 1 | N13: 1 | O13: =VLOOKUP(N13,Veriler!A$1:C$8,2,FALSE) -> 5 x Rose | P13: =IF(I13<VLOOKUP(N13,Veriler!A$1:E$8,5,FALSE)," UYGUNDUR","KESİT AKIMI TAŞIYAMIYOR") -> UYGUNDUR
A14: 81 | B14: 81 | C14: 26 | D14: 3 | E14: 45 | F14: =C14*D14*E14 -> 3510 | G14: =0.5*(F14+F15+F17) -> 4230 | H14: =G14/(SQRT(3)*380) -> 6.4268201 | M14: =IF(L14>Veriler!$D$1,IF(L14>Veriler!$D$2,IF(L14>Veriler!$D$3,IF(L14>Veriler!$D$4,IF(L14>Veriler!$D$5,IF(L14>Veriler!$D$6,IF(L14>Veriler!$D$7,IF(L14>Veriler!$D$8,"ders sorumlusuna başvur",Veriler!$A$8),Veriler!$A$7),Veriler!$A$6),Veriler!$A$5),Veriler!$A$4),Veriler!$A$3),Veriler!$A$2),Veriler!$A$1) -> 1 | N14: 1 | O14: =VLOOKUP(N14,Veriler!A$1:C$8,2,FALSE) -> 5 x Rose | P14: =IF(I14<VLOOKUP(N14,Veriler!A$1:E$8,5,FALSE)," UYGUNDUR","KESİT AKIMI TAŞIYAMIYOR") -> UYGUNDUR
A15: 82 | B15: 82 | C15: 26 | D15: 3 | E15: 45 | F15: =C15*D15*E15 -> 3510 | G15: =0.5*(F15+F16) -> 3510 | H15: =G15/(SQRT(3)*380) -> 5.3328933 | M15: =IF(L15>Veriler!$D$1,IF(L15>Veriler!$D$2,IF(L15>Veriler!$D$3,IF(L15>Veriler!$D$4,IF(L15>Veriler!$D$5,IF(L15>Veriler!$D$6,IF(L15>Veriler!$D$7,IF(L15>Veriler!$D$8,"ders sorumlusuna başvur",Veriler!$A$8),Veriler!$A$7),Veriler!$A$6),Veriler!$A$5),Veriler!$A$4),Veriler!$A$3),Veriler!$A$2),Veriler!$A$1) -> 1 | N15: 1 | O15: =VLOOKUP(N15,Veriler!A$1:C$8,2,FALSE) -> 5 x Rose | P15: =IF(I15<VLOOKUP(N15,Veriler!A$1:E$8,5,FALSE)," UYGUNDUR","KESİT AKIMI TAŞIYAMIYOR") -> UYGUNDUR
A16: 83 | B16: 83 | C16: 26 | D16: 3 | E16: 45 | F16: =C16*D16*E16 -> 3510 | G16: =0.5*(F16) -> 1755 | H16: =G16/(SQRT(3)*380) -> 2.6664466 | M16: =IF(L16>Veriler!$D$1,IF(L16>Veriler!$D$2,IF(L16>Veriler!$D$3,IF(L16>Veriler!$D$4,IF(L16>Veriler!$D$5,IF(L16>Veriler!$D$6,IF(L16>Veriler!$D$7,IF(L16>Veriler!$D$8,"ders sorumlusuna başvur",Veriler!$A$8),Veriler!$A$7),Veriler!$A$6),Veriler!$A$5),Veriler!$A$4),Veriler!$A$3),Veriler!$A$2),Veriler!$A$1) -> 1 | N16: 1 | O16: =VLOOKUP(N16,Veriler!A$1:C$8,2,FALSE) -> 5 x Rose | P16: =IF(I16<VLOOKUP(N16,Veriler!A$1:E$8,5,FALSE)," UYGUNDUR","KESİT AKIMI TAŞIYAMIYOR") -> UYGUNDUR
A17: 84 | B17: 84 | C17: 16 | D17: 2 | E17: 45 | F17: =C17*D17*E17 -> 1440 | G17: =0.5*(F17+F18) -> 2520 | H17: =G17/(SQRT(3)*380) -> 3.8287439 | M17: =IF(L17>Veriler!$D$1,IF(L17>Veriler!$D$2,IF(L17>Veriler!$D$3,IF(L17>Veriler!$D$4,IF(L17>Veriler!$D$5,IF(L17>Veriler!$D$6,IF(L17>Veriler!$D$7,IF(L17>Veriler!$D$8,"ders sorumlusuna başvur",Veriler!$A$8),Veriler!$A$7),Veriler!$A$6),Veriler!$A$5),Veriler!$A$4),Veriler!$A$3),Veriler!$A$2),Veriler!$A$1) -> 1 | N17: 1 | O17: =VLOOKUP(N17,Veriler!A$1:C$8,2,FALSE) -> 5 x Rose | P17: =IF(I17<VLOOKUP(N17,Veriler!A$1:E$8,5,FALSE)," UYGUNDUR","KESİT AKIMI TAŞIYAMIYOR") -> UYGUNDUR
